Workbook

Sheet Distribution panel 1
D1: Efficiency | E1: 0.8 | G1: CYBERNETIK
D2: Power Factor | E2: 0.8 | G2: Total KW | H2: =SUM(H16,H21) -> 144.9875
D3: Line to Line Voltage | E3: 415 | G3: Total HP | H3: =(H2/$E$5) -> 194.35322
D4: Single Phase voltage | E4: 120 | G4: Total Amp | H4: =(H2*1000)/(1.73*$E$3*$E$2) -> 252.43314
D5: KW to HP Conversion | E5: 0.746 | G5: Design Total KW | H5: =H2*$E$6 -> 178.33462
D6: Design Factor | E6: 1.23 | G6: Design Total HP | H6: =H3*$E$6 -> 239.05446
D7: KVA to KW Conversion | E7: 0.8 | G7: Design Total Amp | H7: =H4*$E$6 -> 310.49277
B9: CYBERNETIK MACHINE
B10: Zone | C10: Sr. No | D10: Device | E10: Name | F10: DOL/VFD/Thyrister | G10: KW | H10: Total (KW) | I10: HP | J10: Amp
B11: System | C11: 1 | D11: Chopper Panel | E11: CP01 | F11: MCCB | G11: ='Chopper Zone Load'!G25 -> 14.7875 | H11: ='Chopper Zone Load'!H25 -> 14.7875 | I11: ='Chopper Zone Load'!I25 -> 19.822386 | J11: ='Chopper Zone Load'!J25 -> 37.478116
C12: 2 | D12: Chopper Panel feeder-1 | E12: CPF01 | F12: MCCB | G12: 29 | H12: =G12 -> 29 | I12: =H12/$E$5 -> 38.873995 | J12: =(H12*1000)/(1.732*$E$1*$E$2*$E$3) -> 63.040847
C13: 3 | D13: Chopper Panel feeder-2 | E13: CPF02 | F13: MCCB | G13: 29 | H13: =G13 -> 29 | I13: =H13/$E$5 -> 38.873995 | J13: =(H13*1000)/(1.732*$E$1*$E$2*$E$3) -> 63.040847
C14: 4 | D14: Dryer panel | E14: DRP01 | F14: MCCB | G14: ='Dryer Zone Load'!G27 -> 51.8 | H14: ='Dryer Zone Load'!H27 -> 51.8 | I14: ='Dryer Zone Load'!I27 -> 69.436997 | J14: ='Dryer Zone Load'!J27 -> 117.10859
C15: 5 | D15: Packing panel | E15: PKP01 | F15: MCCB | G15: ='Packing Zone Load'!G34 -> 20 | H15: ='Packing Zone Load'!H34 -> 20 | I15: ='Packing Zone Load'!I34 -> 26.809651 | J15: ='Packing Zone Load'!J34 -> 49.689818
C16: Total | G16: =SUM(G11:G15) -> 144.5875 | H16: =SUM(H11:H15) -> 144.5875 | I16: =SUM(I11:I15) -> 193.81702 | J16: =SUM(J11:J15) -> 330.35821
B17: Transformer Load
C18: Sr. No | D18: Device | E18: Name | F18: KVA | G18: KW | H18: Total (KW) | I18: HP | J18: P Amp
B19: Control | C19: 1 | D19: Transformer-1 (230VAC) | E19: TR-1 | F19: 0.5 | G19: =F19*$E$7 -> 0.4 | H19: =G19 -> 0.4 | I19: =H19/$E$5 -> 0.53619303 | J19: =(F19*1000)/(1.732*$E$3) -> 0.69562314
D20: (Utility)
C21: Total | G21: =SUM(G19:G20) -> 0.4 | H21: =SUM(H19:H20) -> 0.4 | I21: =SUM(I19:I20) -> 0.53619303 | J21: =SUM(J19:J20) -> 0.69562314
B22: Total Connected | G22: =G16+G21 -> 144.9875 | H22: =H16+H21 -> 144.9875 | I22: =I16+I21 -> 194.35322 | J22: =J16+J21 -> 331.05384
B23: Total Designed(1.23) | G23: =G22*$E$6 -> 178.33462 | H23: =H22*$E$6 -> 178.33462 | I23: =I22*$E$6 -> 239.05446 | J23: =J22*$E$6 -> 407.19622

Sheet Chopper Zone Load
D1: Efficiency | E1: 0.8 | G1: CYBERNETIK
D2: Power Factor | E2: 0.8 | G2: Total KW | H2: =SUM(H18,H23) -> 11.83
D3: Line to Line Voltage | E3: 415 | G3: Total HP | H3: =(H2/$E$5) -> 15.857909
D4: Single Phase voltage | E4: 230 | G4: Total Amp | H4: =(H2*1000)/(1.73*$E$3*$E$2) -> 20.596838
D5: KW to HP Conversion | E5: 0.746 | G5: Design Total KW | H5: =H2*$E$6 -> 14.7875
D6: Design Factor | E6: 1.25 | G6: Design Total HP | H6: =H3*$E$6 -> 19.822386
D7: KVA to KW Conversion | E7: 0.8 | G7: Design Total Amp | H7: =H4*$E$6 -> 25.746048
B9: CYBERNETIK MACHINE
B10: Zone | C10: Sr. No | D10: Device | E10: Name | F10: DOL/VFD/Thyrister | G10: KW | H10: Total (KW) | I10: HP | J10: Amp | K10: Drive amp | L10: Motor KW
B11: System | C11: 1 | D11: Chopper Motor-1 | E11: CM001 | F11: VFD | G11: 4 | H11: =G11 -> 4 | I11: =H11/$E$5 -> 5.3619303 | J11: =(H11*1000)/(1.732*$E$1*$E$2*$E$3) -> 8.6952892 | K11: 10.5 | L11: 3.7
C12: 2 | D12: Chopper Motor-2 | E12: CM002 | F12: VFD | G12: 4 | H12: =G12 -> 4 | I12: =H12/$E$5 -> 5.3619303 | J12: =(H12*1000)/(1.732*$E$1*$E$2*$E$3) -> 8.6952892 | K12: 10.5 | L12: 3.7
C13: 3 | D13: Anti-Static Coating Roller | E13: ASCR001 | F13: VFD | G13: 0.75 | H13: =G13 -> 0.75 | I13: =H13/$E$5 -> 1.0053619 | J13: =(H13*1000)/(1.732*$E$1*$E$2*$E$3) -> 1.6303667 | K13: 2.3 | L13: 0.5
C14: 4 | D14: Spreader Motor-2 | E14: SM001 | F14: VFD | G14: 0.75 | H14: =G14 -> 0.75 | I14: =H14/$E$5 -> 1.0053619 | J14: =(H14*1000)/(1.732*$E$1*$E$2*$E$3) -> 1.6303667 | K14: 2.3 | L14: 0.5
C15: 5 | D15: Feeders-1 (In Future Scope with DOL) | E15: - | F15: DOL | G15: 0.18 | H15: =G15 -> 0.18 | I15: =H15/$E$5 -> 0.24128686 | J15: =(H15*1000)/(1.732*$E$1*$E$2*$E$3) -> 0.39128802 | K15: 0.4 | L15: 0.18
C16: 6 | D16: Feeders-2 (In Future Scope with DOL) | E16: - | F16: DOL | G16: 0.18 | H16: =G16 -> 0.18 | I16: =H16/$E$5 -> 0.24128686 | J16: =(H16*1000)/(1.732*$E$1*$E$2*$E$3) -> 0.39128802 | K16: 0.4 | L16: 0.18
C17: 7 | D17: Feeders-3 (In Future Scope with DOL) | E17: - | F17: DOL | G17: 0.37 | H17: =G17 -> 0.37 | I17: =H17/$E$5 -> 0.49597855 | J17: =(H17*1000)/(1.732*$E$1*$E$2*$E$3) -> 0.80431425 | K17: 0.8 | L17: 0.37
C18: Total | G18: =SUM(G11:G17) -> 10.23 | H18: =SUM(H11:H17) -> 10.23 | I18: =SUM(I11:I17) -> 13.713137 | J18: =SUM(J11:J17) -> 22.238202 | K18: =SUM(K11:K17) -> 27.2
B19: Transformer Load
C20: Sr. No | D20: Device | E20: Name | F20: KVA | G20: KW | H20: Total (KW) | I20: HP | J20: P Amp | K20: S Amp
B21: Control | C21: 1 | D21: Transformer-1 (230VAC) | E21: TR-1 | F21: 2 | G21: =F21*$E$7 -> 1.6 | H21: =G21 -> 1.6 | I21: =H21/$E$5 -> 2.1447721 | J21: =(F21*1000)/(1.732*$E$3) -> 2.7824926 | K21: =(G21*1000)/(1.732*$E$4) -> 4.0164675
D22: (PLC, HMI, I/O)
C23: Total | G23: =SUM(G21:G22) -> 1.6 | H23: =SUM(H21:H22) -> 1.6 | I23: =SUM(I21:I22) -> 2.1447721 | J23: =SUM(J21:J22) -> 2.7824926
B24: Total Connected | G24: =G18+G23 -> 11.83 | H24: =H18+H23 -> 11.83 | I24: =I18+I23 -> 15.857909 | J24: =K18+J23 -> 29.982493
B25: Total Designed(1.25) | G25: =G24*$E$6 -> 14.7875 | H25: =H24*$E$6 -> 14.7875 | I25: =I24*$E$6 -> 19.822386 | J25: =J24*$E$6 -> 37.478116
K51: 2 Nodes

Sheet Dryer Zone Load
D1: Efficiency | E1: 0.8 | G1: CYBERNETIK
D2: Power Factor | E2: 0.8 | G2: Total KW | H2: =SUM(H20,H25) -> 41.44
D3: Line to Line Voltage | E3: 415 | G3: Total HP | H3: =(H2/$E$5) -> 55.549598
D4: Single Phase voltage | E4: 230 | G4: Total Amp | H4: =(H2*1000)/(1.73*$E$3*$E$2) -> 72.149871
D5: KW to HP Conversion | E5: 0.746 | G5: Design Total KW | H5: =H2*$E$6 -> 51.8
D6: Design Factor | E6: 1.25 | G6: Design Total HP | H6: =H3*$E$6 -> 69.436997
D7: KVA to KW Conversion | E7: 0.8 | G7: Design Total Amp | H7: =H4*$E$6 -> 90.187339
B9: CYBERNETIK MACHINE
B10: Zone | C10: Sr. No | D10: Device | E10: Name | F10: DOL/VFD/Thyrister | G10: KW | H10: Total (KW) | I10: HP | J10: Amp | K10: Drive amp | L10: Motor KW
B11: System | C11: 1 | D11: Dryer Heating Zone Inlet Blower | E11: DHIB01 | F11: VFD | G11: 11 | H11: =G11 -> 11 | I11: =H11/$E$5 -> 14.745308 | J11: =(H11*1000)/(1.732*$E$1*$E$2*$E$3) -> 23.912045 | K11: 24 | L11: 11
C12: 2 | D12: Dryer Heating Zone Dust Collector | E12: DHDC01 | F12: VFD | G12: 11 | H12: =G12 -> 11 | I12: =H12/$E$5 -> 14.745308 | J12: =(H12*1000)/(1.732*$E$1*$E$2*$E$3) -> 23.912045 | K12: 24 | L12: 11
C13: 3 | D13: Dryer Cooling Zone Inlet Blower | E13: DCIB01 | F13: VFD | G13: 5.5 | H13: =G13 -> 5.5 | I13: =H13/$E$5 -> 7.3726542 | J13: =(H13*1000)/(1.732*$E$1*$E$2*$E$3) -> 11.956023 | K13: 13 | L13: 5.5
C14: 4 | D14: Dryer Cooling Zone Dust Collector | E14: DCDC01 | F14: VFD | G14: 7.5 | H14: =G14 -> 7.5 | I14: =H14/$E$5 -> 10.053619 | J14: =(H14*1000)/(1.732*$E$1*$E$2*$E$3) -> 16.303667 | K14: 17 | L14: 7.5
C15: 5 | D15: Dryer Conveyor Motor | E15: DCM01 | F15: VFD | G15: 1.5 | H15: =G15 -> 1.5 | I15: =H15/$E$5 -> 2.0107239 | J15: =(H15*1000)/(1.732*$E$1*$E$2*$E$3) -> 3.2607335 | K15: 4 | L15: 1.1
C16: 6 | D16: Dryer Outlet Vibratory feeder-1 | E16: DOVF01 | F16: VFD | G16: 1.5 | H16: =G16 -> 1.5 | I16: =H16/$E$5 -> 2.0107239 | J16: =(H16*1000)/(1.732*$E$1*$E$2*$E$3) -> 3.2607335 | K16: 4 | L16: 1.1
C17: 7 | D17: Dryer Outlet Vibratory feeder-2 | E17: DOVF02 | F17: VFD | G17: 1.5 | H17: =G17 -> 1.5 | I17: =H17/$E$5 -> 2.0107239 | J17: =(H17*1000)/(1.732*$E$1*$E$2*$E$3) -> 3.2607335 | K17: 4 | L17: 1.1
C18: 8 | D18: Brush Roller Motor-1 | E18: BRM01 | F18: DOL | G18: 0.37 | H18: =G18 -> 0.37 | I18: =H18/$E$5 -> 0.49597855 | J18: =(H18*1000)/(1.732*$E$1*$E$2*$E$3) -> 0.80431425 | K18: 0.8 | L18: 0.37
C19: 9 | D19: Brush Roller Motor-2 | E19: BRM02 | F19: DOL | G19: 0.37 | H19: =G19 -> 0.37 | I19: =H19/$E$5 -> 0.49597855 | J19: =(H19*1000)/(1.732*$E$1*$E$2*$E$3) -> 0.80431425 | K19: 0.8 | L19: 0.37
C20: Total | G20: =SUM(G11:G19) -> 40.24 | H20: =SUM(H11:H19) -> 40.24 | I20: =SUM(I11:I19) -> 53.941019 | J20: =SUM(J11:J19) -> 87.47461 | K20: =SUM(K11:K19) -> 91.6
B21: Transformer Load
C22: Sr. No | D22: Device | E22: Name | F22: KVA | G22: KW | H22: Total (KW) | I22: HP | J22: P Amp | K22: S Amp
B23: Control | C23: 1 | D23: Transformer-1 (230VAC) | E23: TR-1 | F23: 1.5 | G23: =F23*$E$7 -> 1.2 | H23: =G23 -> 1.2 | I23: =H23/$E$5 -> 1.6085791 | J23: =(F23*1000)/(1.732*$E$3) -> 2.0868694 | K23: =(G23*1000)/(1.732*$E$4) -> 3.0123506
D24: (PLC, HMI, I/O)
C25: Total | G25: =SUM(G23:G24) -> 1.2 | H25: =SUM(H23:H24) -> 1.2 | I25: =SUM(I23:I24) -> 1.6085791 | J25: =SUM(J23:J24) -> 2.0868694
B26: Total Connected | G26: =G20+G25 -> 41.44 | H26: =H20+H25 -> 41.44 | I26: =I20+I25 -> 55.549598 | J26: =K20+J25 -> 93.686869
B27: Total Designed(1.25) | G27: =G26*$E$6 -> 51.8 | H27: =H26*$E$6 -> 51.8 | I27: =I26*$E$6 -> 69.436997 | J27: =J26*$E$6 -> 117.10859
K53: 2 Nodes

Sheet Packing Zone Load
D1: Efficiency | E1: 0.8 | G1: CYBERNETIK
D2: Power Factor | E2: 0.8 | G2: Total KW | H2: =SUM(H23,H32) -> 16
D3: Line to Line Voltage | E3: 415 | G3: Total HP | H3: =(H2/$E$5) -> 21.447721
D4: Single Phase voltage | E4: 230 | G4: Total Amp | H4: =(H2*1000)/(1.73*$E$3*$E$2) -> 27.857093
D5: KW to HP Conversion | E5: 0.746 | G5: Design Total KW | H5: =H2*$E$6 -> 20
D6: Design Factor | E6: 1.25 | G6: Design Total HP | H6: =H3*$E$6 -> 26.809651
D7: KVA to KW Conversion | E7: 0.8 | G7: Design Total Amp | H7: =H4*$E$6 -> 34.821366
B9: CYBERNETIK MACHINE
B10: Zone | C10: Sr. No | D10: Device | E10: Name | F10: DOL/VFD/Thyrister | G10: KW | H10: Total (KW) | I10: HP | J10: Amp | K10: Drive amp | L10: Motor KW
B11: System | C11: 1 | D11: Incliend Belt conveyor | E11: IBC001 | F11: VFD | G11: 1.5 | H11: =G11 -> 1.5 | I11: =H11/$E$5 -> 2.0107239 | J11: =(H11*1000)/(1.732*$E$1*$E$2*$E$3) -> 3.2607335 | K11: 4 | L11: 1.1
C12: 2 | D12: Material Storage Vibro-1 | E12: MSV01 | F12: VFD | G12: 1.5 | H12: =G12 -> 1.5 | I12: =H12/$E$5 -> 2.0107239 | J12: =(H12*1000)/(1.732*$E$1*$E$2*$E$3) -> 3.2607335 | K12: 4 | L12: 1.1
C13: 3 | D13: Material Storage Vibro-2 | E13: MSV02 | F13: VFD | G13: 1.5 | H13: =G13 -> 1.5 | I13: =H13/$E$5 -> 2.0107239 | J13: =(H13*1000)/(1.732*$E$1*$E$2*$E$3) -> 3.2607335 | K13: 4 | L13: 1.1
C14: 4 | D14: Bag Filling Conveyor | E14: BFC01 | F14: VFD | G14: 0.75 | H14: =G14 -> 0.75 | I14: =H14/$E$5 -> 1.0053619 | J14: =(H14*1000)/(1.732*$E$1*$E$2*$E$3) -> 1.6303667 | K14: 2.3 | L14: 0.75
C15: 5 | D15: Bag Sealing & Stiching Conveyor | E15: BSSC01 | F15: VFD | G15: 0.75 | H15: =G15 -> 0.75 | I15: =H15/$E$5 -> 1.0053619 | J15: =(H15*1000)/(1.732*$E$1*$E$2*$E$3) -> 1.6303667 | K15: 2.3 | L15: 0.75
C16: 6 | D16: Bag Stitching Motor | E16: BSTM01 | F16: DOL | G16: 0.75 | H16: =G16 -> 0.75 | I16: =H16/$E$5 -> 1.0053619 | J16: =(H16*1000)/(1.732*$E$1*$E$2*$E$3) -> 1.6303667 | K16: 1.6 | L16: 0.75
C17: 7 | D17: Bag Tilting Conveyor | E17: BTC01 | F17: VFD | G17: 0.75 | H17: =G17 -> 0.75 | I17: =H17/$E$5 -> 1.0053619 | J17: =(H17*1000)/(1.732*$E$1*$E$2*$E$3) -> 1.6303667 | K17: 2.3 | L17: 0.75
C18: 8 | D18: Bag Flattening Bottom Conveyor | E18: BFBC01 | F18: VFD | G18: 0.75 | H18: =G18 -> 0.75 | I18: =H18/$E$5 -> 1.0053619 | J18: =(H18*1000)/(1.732*$E$1*$E$2*$E$3) -> 1.6303667 | K18: 2.3 | L18: 0.75
C19: 9 | D19: Bag Flattening Top Conveyor | E19: BFTC01 | F19: VFD | G19: 0.75 | H19: =G19 -> 0.75 | I19: =H19/$E$5 -> 1.0053619 | J19: =(H19*1000)/(1.732*$E$1*$E$2*$E$3) -> 1.6303667 | K19: 2.3 | L19: 0.75
C20: 10 | D20: Metal Detector Conveyor | E20: MDC01 | F20: VFD | G20: 0.75 | H20: =G20 -> 0.75 | I20: =H20/$E$5 -> 1.0053619 | J20: =(H20*1000)/(1.732*$E$1*$E$2*$E$3) -> 1.6303667 | K20: 2.3 | L20: 0.75
C21: 11 | D21: Bag Rejection Conveyor | E21: BRC01 | F21: VFD | G21: 0.75 | H21: =G21 -> 0.75 | I21: =H21/$E$5 -> 1.0053619 | J21: =(H21*1000)/(1.732*$E$1*$E$2*$E$3) -> 1.6303667 | K21: 2.3 | L21: 0.75
C22: 12 | D22: Bagging Zone Dust Collector | E22: BDCB01 | F22: DOL | G22: 1.1 | H22: =G22 -> 1.1 | I22: =H22/$E$5 -> 1.4745308 | J22: =(H22*1000)/(1.732*$E$1*$E$2*$E$3) -> 2.3912045 | K22: 2.4 | L22: 1.1
C23: Total | G23: =SUM(G11:G22) -> 11.6 | H23: =SUM(H11:H22) -> 11.6 | I23: =SUM(I11:I22) -> 15.549598 | J23: =SUM(J11:J22) -> 25.216339 | K23: =SUM(K11:K22) -> 32.1
B24: Transformer Load
C25: Sr. No | D25: Device | E25: Name | F25: KVA | G25: KW | H25: Total (KW) | I25: HP | J25: P Amp | K25: S Amp
B26: Control | C26: 1 | D26: Transformer-1 (230VAC) | E26: TR-1 | F26: 1.5 | G26: =F26*$E$7 -> 1.2 | H26: =G26 -> 1.2 | I26: =H26/$E$5 -> 1.6085791 | J26: =(F26*1000)/(1.732*$E$3) -> 2.0868694 | K26: =(G26*1000)/(1.732*$E$4) -> 3.0123506
D27: (PLC, HMI, I/O)
B28: Device | C28: 2 | D28: Transformer-2 (230VAC) | E28: TR-2 | F28: 4 | G28: =F28*$E$7 -> 3.2 | H28: =G28 -> 3.2 | I28: =H28/$E$5 -> 4.2895442 | J28: =(F28*1000)/(1.732*$E$3) -> 5.5649851 | K28: =(G28*1000)/(1.732*$E$4) -> 8.032935
D29: Metal Detector (0.5KW)
C30: 3 | D30: Sealing Station (0.75KW) | F30: 0 | G30: =F30*$E$7 -> 0 | H30: =G30 -> 0 | I30: =H30/$E$5 -> 0 | J30: =(F30*1000)/(1.732*$E$3) -> 0 | K30: =(G30*1000)/(1.732*$E$4) -> 0
D31: Electro Magnetic Vibro-1 and 2 (0.75X2=1.5KW)
C32: Total | G32: =SUM(G26:G30) -> 4.4 | H32: =SUM(H26:H30) -> 4.4 | I32: =SUM(I26:I30) -> 5.8981233 | J32: =SUM(J26:J30) -> 7.6518545
B33: Total Connected | G33: =G23+G32 -> 16 | H33: =H23+H32 -> 16 | I33: =I23+I32 -> 21.447721 | J33: =K23+J32 -> 39.751855
B34: Total Designed(1.25) | G34: =G33*$E$6 -> 20 | H34: =H33*$E$6 -> 20 | I34: =I33*$E$6 -> 26.809651 | J34: =J33*$E$6 -> 49.689818
K55: 2 Nodes

Sheet Chopper IO List
A4: DI | J4: DO
A5: Sl No | B5: Input Type | C5: Location | D5: Address | F5: Input Description | G5: Input Tags | H5: Device | I5: TAG | J5: Sl No | K5: Output Type | L5: Location | M5: Address | N5: Output Description | O5: Output Tags | P5: Device | Q5: TAG
F6: DIGITAL INPUT | G6: Input Tags | N6: DIGITAL OUTPUT
A7: 1 | B7: SDI01 | D7: RC:I:1.0 | E7: _ | F7: Chopper-1 E-Stop 1/1 | G7: =CONCATENATE(B7,E7,F7) -> SDI01_Chopper-1 E-Stop 1/1 | H7: E-Stop Button | J7: 1 | K7: SDO01 | M7: RC:O:2.0 | N7: Chopper Safety Healhy 1/1 | O7: =CONCATENATE(K7,E7,N7) -> SDO01_Chopper Safety Healhy 1/1 | P7: Safety Relay (STO)
A8: 2 | B8: SDI02 | D8: RC:I:1.1 | E8: _ | F8: Chopper-1 E-Stop 1/2 | G8: =CONCATENATE(B8,E8,F8) -> SDI02_Chopper-1 E-Stop 1/2 | H8: E-Stop Button | J8: 2 | K8: SDO02 | M8: RC:O:2.1 | N8: Chopper Safety Healhy 1/2 | O8: =CONCATENATE(K8,E8,N8) -> SDO02_Chopper Safety Healhy 1/2 | P8: Safety Relay (STO)
A9: 3 | B9: SDI03 | D9: RC:I:1.2 | E9: _ | F9: Chopper-2 E-Stop 1/1 | G9: =CONCATENATE(B9,E9,F9) -> SDI03_Chopper-2 E-Stop 1/1 | H9: E-Stop Button | J9: 3 | K9: SDO03 | M9: RC:O:2.2 | N9: Spare | O9: =CONCATENATE(K9,E9,N9) -> SDO03_Spare
A10: 4 | B10: SDI04 | D10: RC:I:1.3 | E10: _ | F10: Chopper-2 E-Stop 1/2 | G10: =CONCATENATE(B10,E10,F10) -> SDI04_Chopper-2 E-Stop 1/2 | H10: E-Stop Button | J10: 4 | K10: SDO04 | M10: RC:O:2.3 | N10: Spare | O10: =CONCATENATE(K10,E10,N10) -> SDO04_Spare
A11: 5 | B11: SDI05 | D11: RC:I:1.4 | E11: _ | F11: Spreader E-Stop 1/1 | G11: =CONCATENATE(B11,E11,F11) -> SDI05_Spreader E-Stop 1/1 | H11: E-Stop Button | J11: 5 | K11: SDO05 | M11: RC:O:2.4 | N11: Spare | O11: =CONCATENATE(K11,E11,N11) -> SDO05_Spare
A12: 6 | B12: SDI06 | D12: RC:I:1.5 | E12: _ | F12: Spreader E-Stop 1/2 | G12: =CONCATENATE(B12,E12,F12) -> SDI06_Spreader E-Stop 1/2 | H12: E-Stop Button | J12: 6 | K12: SDO06 | M12: RC:O:2.5 | N12: Spare | O12: =CONCATENATE(K12,E12,N12) -> SDO06_Spare
A13: 7 | B13: SDI07 | D13: RC:I:1.6 | E13: _ | F13: Applicator E-Stop 1/1 | G13: =CONCATENATE(B13,E13,F13) -> SDI07_Applicator E-Stop 1/1 | H13: E-Stop Button | J13: 7 | K13: SDO07 | M13: RC:O:2.6 | N13: Air Relief Valve1/1 | O13: =CONCATENATE(K13,E13,N13) -> SDO07_Air Relief Valve1/1
A14: 8 | B14: SDI08 | D14: RC:I:1.7 | E14: _ | F14: Applicator E-Stop 1/2 | G14: =CONCATENATE(B14,E14,F14) -> SDI08_Applicator E-Stop 1/2 | H14: E-Stop Button | J14: 8 | K14: SDO08 | M14: RC:O:2.7 | N14: Air Relief Valve1/2 | O14: =CONCATENATE(K14,E14,N14) -> SDO08_Air Relief Valve1/2
A15: 1 | B15: DI01 | D15: RC:I:3.0 | E15: _ | F15: System Start PB | G15: =CONCATENATE(B15,E15,F15) -> DI01_System Start PB | H15: Push Button+Lamp | J15: 1 | K15: DO01 | M15: RC:O:10.0 | N15: Chopper Tower Lamp Red | O15: =CONCATENATE(K15,E15,N15) -> DO01_Chopper Tower Lamp Red | P15: Tower Lamp
A16: 2 | B16: DI02 | D16: RC:I:3.1 | E16: _ | F16: System Stop PB | G16: =CONCATENATE(B16,E16,F16) -> DI02_System Stop PB | H16: Push Button | J16: 2 | K16: DO02 | M16: RC:O:10.1 | N16: Chopper Tower Lamp Amber | O16: =CONCATENATE(K16,E16,N16) -> DO02_Chopper Tower Lamp Amber | P16: Tower Lamp
A17: 3 | B17: DI03 | D17: RC:I:3.2 | E17: _ | F17: System Reset PB | G17: =CONCATENATE(B17,E17,F17) -> DI03_System Reset PB | H17: Push Button+Lamp | J17: 3 | K17: DO03 | M17: RC:O:10.2 | N17: Chopper Tower Lamp Green | O17: =CONCATENATE(K17,E17,N17) -> DO03_Chopper Tower Lamp Green | P17: Tower Lamp
A18: 4 | B18: DI04 | D18: RC:I:3.3 | E18: _ | F18: Safety Reset PB | G18: =CONCATENATE(B18,E18,F18) -> DI04_Safety Reset PB | H18: Push Button+Lamp | J18: 4 | K18: DO04 | M18: RC:O:10.3 | N18: Chopper Tower Lamp Buzzer | O18: =CONCATENATE(K18,E18,N18) -> DO04_Chopper Tower Lamp Buzzer | P18: Tower Lamp
A19: 5 | B19: DI05 | D19: RC:I:3.4 | E19: _ | F19: Spare DI | G19: =CONCATENATE(B19,E19,F19) -> DI05_Spare DI | J19: 5 | K19: DO05 | M19: RC:O:10.4 | N19: Chopper System Start PB Green Lamp | O19: =CONCATENATE(K19,E19,N19) -> DO05_Chopper System Start PB Green Lamp | P19: Push Button+Lamp
A20: 6 | B20: DI06 | D20: RC:I:3.5 | E20: _ | F20: Spare DI | G20: =CONCATENATE(B20,E20,F20) -> DI06_Spare DI | J20: 6 | K20: DO06 | M20: RC:O:10.5 | N20: Chopper System Reset PB Blue Lamp | O20: =CONCATENATE(K20,E20,N20) -> DO06_Chopper System Reset PB Blue Lamp | P20: Push Button+Lamp
A21: 7 | B21: DI07 | D21: RC:I:3.6 | E21: _ | F21: 3 Phase Supply Ok | G21: =CONCATENATE(B21,E21,F21) -> DI07_3 Phase Supply Ok | H21: Phase Failure Relay | J21: 7 | K21: DO07 | M21: RC:O:10.6 | N21: Chopper System Safety Reset PB Yellow Lamp | O21: =CONCATENATE(K21,E21,N21) -> DO07_Chopper System Safety Reset PB Yellow Lamp | P21: Push Button+Lamp
A22: 8 | B22: DI08 | D22: RC:I:3.7 | E22: _ | F22: Chopper Air Pressure Switch | G22: =CONCATENATE(B22,E22,F22) -> DI08_Chopper Air Pressure Switch | H22: Air Pressure Switch | J22: 8 | K22: DO08 | M22: RC:O:10.7 | N22: Spare DO | O22: =CONCATENATE(K22,E22,N22) -> DO08_Spare DO
A23: 9 | B23: DI09 | D23: RC:I:4.0 | E23: _ | F23: Chopper-1 Local/Remote SS | G23: =CONCATENATE(B23,E23,F23) -> DI09_Chopper-1 Local/Remote SS | H23: Selector Switch | J23: 9 | K23: DO09 | M23: RC:O:11.0 | N23: Chopper-1 Start PB Lamp | O23: =CONCATENATE(K23,E23,N23) -> DO09_Chopper-1 Start PB Lamp
A24: 10 | B24: DI10 | D24: RC:I:4.1 | E24: _ | F24: Chopper-1 Start PB | G24: =CONCATENATE(B24,E24,F24) -> DI10_Chopper-1 Start PB | H24: Push Button+Lamp | J24: 10 | K24: DO10 | M24: RC:O:11.1 | N24: Chopper-1 PU Cylinder-1 Fwd SOV | O24: =CONCATENATE(K24,E24,N24) -> DO10_Chopper-1 PU Cylinder-1 Fwd SOV
A25: 11 | B25: DI11 | D25: RC:I:4.2 | E25: _ | F25: Chopper-1 Stop PB | G25: =CONCATENATE(B25,E25,F25) -> DI11_Chopper-1 Stop PB | H25: Push Button | J25: 11 | K25: DO11 | M25: RC:O:11.2 | N25: Chopper-1 PU Cylinder-1 Rev SOV | O25: =CONCATENATE(K25,E25,N25) -> DO11_Chopper-1 PU Cylinder-1 Rev SOV
A26: 12 | B26: DI12 | D26: RC:I:4.3 | E26: _ | F26: Spare DI | G26: =CONCATENATE(B26,E26,F26) -> DI12_Spare DI | J26: 12 | K26: DO12 | M26: RC:O:11.3 | N26: Chopper-1 PU Cylinder-2 Fwd SOV | O26: =CONCATENATE(K26,E26,N26) -> DO12_Chopper-1 PU Cylinder-2 Fwd SOV
A27: 13 | B27: DI13 | D27: RC:I:4.4 | E27: _ | F27: Chopper-2 Local/Remote SS | G27: =CONCATENATE(B27,E27,F27) -> DI13_Chopper-2 Local/Remote SS | H27: Selector Switch | J27: 13 | K27: DO13 | M27: RC:O:11.4 | N27: Chopper-1 PU Cylinder-2 Rev SOV | O27: =CONCATENATE(K27,E27,N27) -> DO13_Chopper-1 PU Cylinder-2 Rev SOV
A28: 14 | B28: DI14 | D28: RC:I:4.5 | E28: _ | F28: Chopper-2 Start PB | G28: =CONCATENATE(B28,E28,F28) -> DI14_Chopper-2 Start PB | H28: Push Button+Lamp | J28: 14 | K28: DO14 | M28: RC:O:11.5 | N28: Chopper-1 Pressure Roller Cylinder Fwd SOV | O28: =CONCATENATE(K28,E28,N28) -> DO14_Chopper-1 Pressure Roller Cylinder Fwd SOV
A29: 15 | B29: DI15 | D29: RC:I:4.6 | E29: _ | F29: Chopper-2 Stop PB | G29: =CONCATENATE(B29,E29,F29) -> DI15_Chopper-2 Stop PB | H29: Push Button | J29: 15 | K29: DO15 | M29: RC:O:11.6 | N29: Chopper-1 Pressure Roller Cylinder Rev SOV | O29: =CONCATENATE(K29,E29,N29) -> DO15_Chopper-1 Pressure Roller Cylinder Rev SOV
A30: 16 | B30: DI16 | D30: RC:I:4.7 | E30: _ | F30: Spare DI | G30: =CONCATENATE(B30,E30,F30) -> DI16_Spare DI | J30: 16 | K30: DO16 | M30: RC:O:11.7 | N30: Spare DO | O30: =CONCATENATE(K30,E30,N30) -> DO16_Spare DO
A31: 17 | B31: DI17 | D31: RC:I:5.0 | E31: _ | F31: Chopper-1 PU Cylinder-1 Fwd FB | G31: =CONCATENATE(B31,E31,F31) -> DI17_Chopper-1 PU Cylinder-1 Fwd FB | H31: Reed Switch | J31: 17 | K31: DO17 | M31: RC:O:12.0 | N31: Chopper-2 Start PB Lamp | O31: =CONCATENATE(K31,E31,N31) -> DO17_Chopper-2 Start PB Lamp
A32: 18 | B32: DI18 | D32: RC:I:5.1 | E32: _ | F32: Chopper-1 PU Cylinder-1 Rev FB | G32: =CONCATENATE(B32,E32,F32) -> DI18_Chopper-1 PU Cylinder-1 Rev FB | H32: Reed Switch | J32: 18 | K32: DO18 | M32: RC:O:12.1 | N32: Chopper-2 PU Cylinder-1 Fwd SOV | O32: =CONCATENATE(K32,E32,N32) -> DO18_Chopper-2 PU Cylinder-1 Fwd SOV
A33: 19 | B33: DI19 | D33: RC:I:5.2 | E33: _ | F33: Chopper-1 PU Cylinder-2 Fwd FB | G33: =CONCATENATE(B33,E33,F33) -> DI19_Chopper-1 PU Cylinder-2 Fwd FB | H33: Reed Switch | J33: 19 | K33: DO19 | M33: RC:O:12.2 | N33: Chopper-2 PU Cylinder-1 Rev SOV | O33: =CONCATENATE(K33,E33,N33) -> DO19_Chopper-2 PU Cylinder-1 Rev SOV
A34: 20 | B34: DI20 | D34: RC:I:5.3 | E34: _ | F34: Chopper-1 PU Cylinder-2 Rev FB | G34: =CONCATENATE(B34,E34,F34) -> DI20_Chopper-1 PU Cylinder-2 Rev FB | H34: Reed Switch | J34: 20 | K34: DO20 | M34: RC:O:12.3 | N34: Chopper-2 PU Cylinder-2 Fwd SOV | O34: =CONCATENATE(K34,E34,N34) -> DO20_Chopper-2 PU Cylinder-2 Fwd SOV
A35: 21 | B35: DI21 | D35: RC:I:5.4 | E35: _ | F35: Chopper-1 Pressure Roller Cylinder Fwd FB | G35: =CONCATENATE(B35,E35,F35) -> DI21_Chopper-1 Pressure Roller Cylinder Fwd FB | H35: Reed Switch | J35: 21 | K35: DO21 | M35: RC:O:12.4 | N35: Chopper-2 PU Cylinder-2 Rev SOV | O35: =CONCATENATE(K35,E35,N35) -> DO21_Chopper-2 PU Cylinder-2 Rev SOV
A36: 22 | B36: DI22 | D36: RC:I:5.5 | E36: _ | F36: Chopper-1 Pressure Roller Cylinder Rev FB | G36: =CONCATENATE(B36,E36,F36) -> DI22_Chopper-1 Pressure Roller Cylinder Rev FB | H36: Reed Switch | J36: 22 | K36: DO22 | M36: RC:O:12.5 | N36: Chopper-2 Pressure Roller Cylinder Fwd SOV | O36: =CONCATENATE(K36,E36,N36) -> DO22_Chopper-2 Pressure Roller Cylinder Fwd SOV
A37: 23 | B37: DI23 | D37: RC:I:5.6 | E37: _ | F37: Spare DI | G37: =CONCATENATE(B37,E37,F37) -> DI23_Spare DI | J37: 23 | K37: DO23 | M37: RC:O:12.6 | N37: Chopper-2 Pressure Roller Cylinder Rev SOV | O37: =CONCATENATE(K37,E37,N37) -> DO23_Chopper-2 Pressure Roller Cylinder Rev SOV
A38: 24 | B38: DI24 | D38: RC:I:5.7 | E38: _ | F38: Spare DI | G38: =CONCATENATE(B38,E38,F38) -> DI24_Spare DI | J38: 24 | K38: DO24 | M38: RC:O:12.7 | N38: Spare DO | O38: =CONCATENATE(K38,E38,N38) -> DO24_Spare DO
A39: 25 | B39: DI25 | D39: RC:I:6.0 | E39: _ | F39: Chopper-2 PU Cylinder-1 Fwd FB | G39: =CONCATENATE(B39,E39,F39) -> DI25_Chopper-2 PU Cylinder-1 Fwd FB | H39: Reed Switch | J39: 25 | K39: DO25 | M39: RC:O:13.0 | N39: Spreader Start PB Lamp | O39: =CONCATENATE(K39,E39,N39) -> DO25_Spreader Start PB Lamp
A40: 26 | B40: DI26 | D40: RC:I:6.1 | E40: _ | F40: Chopper-2 PU Cylinder-1 Rev FB | G40: =CONCATENATE(B40,E40,F40) -> DI26_Chopper-2 PU Cylinder-1 Rev FB | H40: Reed Switch | J40: 26 | K40: DO26 | M40: RC:O:13.1 | N40: Applicator Start PB Lamp | O40: =CONCATENATE(K40,E40,N40) -> DO26_Applicator Start PB Lamp
A41: 27 | B41: DI27 | D41: RC:I:6.2 | E41: _ | F41: Chopper-2 PU Cylinder-2 Fwd FB | G41: =CONCATENATE(B41,E41,F41) -> DI27_Chopper-2 PU Cylinder-2 Fwd FB | H41: Reed Switch | J41: 27 | K41: DO27 | M41: RC:O:13.2 | N41: Spare DO | O41: =CONCATENATE(K41,E41,N41) -> DO27_Spare DO
A42: 28 | B42: DI28 | D42: RC:I:6.3 | E42: _ | F42: Chopper-2 PU Cylinder-2 Rev FB | G42: =CONCATENATE(B42,E42,F42) -> DI28_Chopper-2 PU Cylinder-2 Rev FB | H42: Reed Switch | J42: 28 | K42: DO28 | M42: RC:O:13.3 | N42: Spare DO | O42: =CONCATENATE(K42,E42,N42) -> DO28_Spare DO
A43: 29 | B43: DI29 | D43: RC:I:6.4 | E43: _ | F43: Chopper-2 Pressure Roller Cylinder Fwd FB | G43: =CONCATENATE(B43,E43,F43) -> DI29_Chopper-2 Pressure Roller Cylinder Fwd FB | H43: Reed Switch | J43: 29 | K43: DO29 | M43: RC:O:13.4 | N43: Spare DO | O43: =CONCATENATE(K43,E43,N43) -> DO29_Spare DO
...

Sheet Dryer IO List
A4: DI | J4: DO
A5: Sl No | B5: Input Type | C5: Location | D5: Address | F5: Input Description | G5: Input Tags | H5: Device | I5: TAG | J5: Sl No | K5: Output Type | L5: Location | M5: Address | N5: Output Description | O5: Output Tags | P5: Device | Q5: TAG
F6: DIGITAL INPUT | G6: Input Tags | N6: DIGITAL OUTPUT
A7: 1 | B7: SDI01 | D7: RD:1:I.0 | E7: _ | F7: Dryer Infeed E-Stop 1/1 | G7: =CONCATENATE(B7,E7,F7) -> SDI01_Dryer Infeed E-Stop 1/1 | H7: E-Stop Button | J7: 1 | K7: SDO01 | M7: RD:O:2.0 | N7: Dryer Safety Healhy 1/1 | O7: =CONCATENATE(K7,E7,N7) -> SDO01_Dryer Safety Healhy 1/1 | P7: Safety Relay (STO)
A8: 2 | B8: SDI02 | D8: RD:1:I.1 | E8: _ | F8: Dryer Infeed E-Stop 1/2 | G8: =CONCATENATE(B8,E8,F8) -> SDI02_Dryer Infeed E-Stop 1/2 | H8: E-Stop Button | J8: 2 | K8: SDO02 | M8: RD:O:2.1 | N8: Dryer Safety Healhy 1/2 | O8: =CONCATENATE(K8,E8,N8) -> SDO02_Dryer Safety Healhy 1/2 | P8: Safety Relay (STO)
A9: 3 | B9: SDI03 | D9: RD:1:I.2 | E9: _ | F9: Dryer Outfeed E-Stop 1/1 | G9: =CONCATENATE(B9,E9,F9) -> SDI03_Dryer Outfeed E-Stop 1/1 | H9: E-Stop Button | J9: 3 | K9: SDO03 | M9: RD:O:2.2 | N9: Spare | O9: =CONCATENATE(K9,E9,N9) -> SDO03_Spare
A10: 4 | B10: SDI04 | D10: RD:1:I.3 | E10: _ | F10: Dryer Outfeed E-Stop 1/2 | G10: =CONCATENATE(B10,E10,F10) -> SDI04_Dryer Outfeed E-Stop 1/2 | H10: E-Stop Button | J10: 4 | K10: SDO04 | M10: RD:O:2.3 | N10: Spare | O10: =CONCATENATE(K10,E10,N10) -> SDO04_Spare
A11: 5 | B11: SDI05 | D11: RD:1:I.4 | E11: _ | F11: Spare | G11: =CONCATENATE(B11,E11,F11) -> SDI05_Spare | J11: 5 | K11: SDO05 | M11: RD:O:2.4 | N11: Spare | O11: =CONCATENATE(K11,E11,N11) -> SDO05_Spare
A12: 6 | B12: SDI06 | D12: RD:1:I.5 | E12: _ | F12: Spare | G12: =CONCATENATE(B12,E12,F12) -> SDI06_Spare | J12: 6 | K12: SDO06 | M12: RD:O:2.5 | N12: Spare | O12: =CONCATENATE(K12,E12,N12) -> SDO06_Spare
A13: 7 | B13: SDI07 | D13: RD:1:I.6 | E13: _ | F13: Spare | G13: =CONCATENATE(B13,E13,F13) -> SDI07_Spare | J13: 7 | K13: SDO07 | M13: RD:O:2.6 | N13: Air Relief Valve1/1 | O13: =CONCATENATE(K13,E13,N13) -> SDO07_Air Relief Valve1/1
A14: 8 | B14: SDI08 | D14: RD:1:I.7 | E14: _ | F14: Spare | G14: =CONCATENATE(B14,E14,F14) -> SDI08_Spare | J14: 8 | K14: SDO08 | M14: RD:O:2.7 | N14: Air Relief Valve1/2 | O14: =CONCATENATE(K14,E14,N14) -> SDO08_Air Relief Valve1/2
A15: 1 | B15: DI01 | D15: RD:3:I.0 | E15: _ | F15: System Start PB | G15: =CONCATENATE(B15,E15,F15) -> DI01_System Start PB | H15: Push Button+Lamp | J15: 1 | K15: DO01 | M15: RD:7:O.0 | N15: Dryer Tower Lamp Red | O15: =CONCATENATE(K15,E15,N15) -> DO01_Dryer Tower Lamp Red | P15: Tower Lamp
A16: 2 | B16: DI02 | D16: RD:3:I.1 | E16: _ | F16: System Stop PB | G16: =CONCATENATE(B16,E16,F16) -> DI02_System Stop PB | H16: Push Button | J16: 2 | K16: DO02 | M16: RD:7:O.1 | N16: Dryer Tower Lamp Amber | O16: =CONCATENATE(K16,E16,N16) -> DO02_Dryer Tower Lamp Amber | P16: Tower Lamp
A17: 3 | B17: DI03 | D17: RD:3:I.2 | E17: _ | F17: System Reset PB | G17: =CONCATENATE(B17,E17,F17) -> DI03_System Reset PB | H17: Push Button+Lamp | J17: 3 | K17: DO03 | M17: RD:7:O.2 | N17: Dryer Tower Lamp Green | O17: =CONCATENATE(K17,E17,N17) -> DO03_Dryer Tower Lamp Green | P17: Tower Lamp
A18: 4 | B18: DI04 | D18: RD:3:I.3 | E18: _ | F18: Safety Reset PB | G18: =CONCATENATE(B18,E18,F18) -> DI04_Safety Reset PB | H18: Push Button+Lamp | J18: 4 | K18: DO04 | M18: RD:7:O.3 | N18: Dryer Tower Lamp Buzzer | O18: =CONCATENATE(K18,E18,N18) -> DO04_Dryer Tower Lamp Buzzer | P18: Tower Lamp
A19: 5 | B19: DI05 | D19: RD:3:I.4 | E19: _ | F19: Spare DI | G19: =CONCATENATE(B19,E19,F19) -> DI05_Spare DI | J19: 5 | K19: DO05 | M19: RD:7:O.4 | N19: Dryer System Start PB Green Lamp | O19: =CONCATENATE(K19,E19,N19) -> DO05_Dryer System Start PB Green Lamp | P19: Push Button+Lamp
A20: 6 | B20: DI06 | D20: RD:3:I.5 | E20: _ | F20: Spare DI | G20: =CONCATENATE(B20,E20,F20) -> DI06_Spare DI | J20: 6 | K20: DO06 | M20: RD:7:O.5 | N20: Dryer System Reset PB Blue Lamp | O20: =CONCATENATE(K20,E20,N20) -> DO06_Dryer System Reset PB Blue Lamp | P20: Push Button+Lamp
A21: 7 | B21: DI07 | D21: RD:3:I.6 | E21: _ | F21: 3 Phase Supply Ok | G21: =CONCATENATE(B21,E21,F21) -> DI07_3 Phase Supply Ok | H21: Phase Failure Relay | J21: 7 | K21: DO07 | M21: RD:7:O.6 | N21: Dryer System Safety Reset PB Yellow Lamp | O21: =CONCATENATE(K21,E21,N21) -> DO07_Dryer System Safety Reset PB Yellow Lamp | P21: Push Button+Lamp
A22: 8 | B22: DI08 | D22: RD:3:I.7 | E22: _ | F22: Dryer Air Pressure | G22: =CONCATENATE(B22,E22,F22) -> DI08_Dryer Air Pressure | H22: Air Pressure Switch | J22: 8 | K22: DO08 | M22: RD:7:O.7 | N22: Spare DO | O22: =CONCATENATE(K22,E22,N22) -> DO08_Spare DO
A23: 9 | B23: DI09 | D23: RD:4:I.0 | E23: _ | F23: Spare DI | G23: =CONCATENATE(B23,E23,F23) -> DI09_Spare DI | J23: 9 | K23: DO09 | M23: RD:8:O.0 | N23: Dryer Outlet Vibratory feeder-1 Enable | O23: =CONCATENATE(K23,E23,N23) -> DO09_Dryer Outlet Vibratory feeder-1 Enable | P23: Contactor
A24: 10 | B24: DI10 | D24: RD:4:I.1 | E24: _ | F24: Spare DI | G24: =CONCATENATE(B24,E24,F24) -> DI10_Spare DI | J24: 10 | K24: DO10 | M24: RD:8:O.1 | N24: Dryer Outlet Vibratory feeder-2 Enable | O24: =CONCATENATE(K24,E24,N24) -> DO10_Dryer Outlet Vibratory feeder-2 Enable | P24: Contactor
A25: 11 | B25: DI11 | D25: RD:4:I.2 | E25: _ | F25: Spare DI | G25: =CONCATENATE(B25,E25,F25) -> DI11_Spare DI | J25: 11 | K25: DO11 | M25: RD:8:O.2 | N25: Dryer Heating Zone Dust Collector PV01 | O25: =CONCATENATE(K25,E25,N25) -> DO11_Dryer Heating Zone Dust Collector PV01 | P25: Pulse Valve Coil
A26: 12 | B26: DI12 | D26: RD:4:I.3 | E26: _ | F26: Spare DI | G26: =CONCATENATE(B26,E26,F26) -> DI12_Spare DI | J26: 12 | K26: DO12 | M26: RD:8:O.3 | N26: Dryer Heating Zone Dust Collector PV02 | O26: =CONCATENATE(K26,E26,N26) -> DO12_Dryer Heating Zone Dust Collector PV02 | P26: Pulse Valve Coil
A27: 13 | B27: DI13 | D27: RD:4:I.4 | E27: _ | F27: Dryer Heating Zone Inlet Blower Disconnector FB | G27: =CONCATENATE(B27,E27,F27) -> DI13_Dryer Heating Zone Inlet Blower Disconnector FB | H27: Disconnector Switch FB | J27: 13 | K27: DO13 | M27: RD:8:O.4 | N27: Dryer Heating Zone Dust Collector PV03 | O27: =CONCATENATE(K27,E27,N27) -> DO13_Dryer Heating Zone Dust Collector PV03 | P27: Pulse Valve Coil
A28: 14 | B28: DI14 | D28: RD:4:I.5 | E28: _ | F28: Dryer Heating Zone Dust Collector Disconnector FB | G28: =CONCATENATE(B28,E28,F28) -> DI14_Dryer Heating Zone Dust Collector Disconnector FB | H28: Disconnector Switch FB | J28: 14 | K28: DO14 | M28: RD:8:O.5 | N28: Dryer Cooling Zone Dust Collector PV01 | O28: =CONCATENATE(K28,E28,N28) -> DO14_Dryer Cooling Zone Dust Collector PV01 | P28: Pulse Valve Coil
A29: 15 | B29: DI15 | D29: RD:4:I.6 | E29: _ | F29: Dryer Cooling Zone Inlet Blower Disconnector FB | G29: =CONCATENATE(B29,E29,F29) -> DI15_Dryer Cooling Zone Inlet Blower Disconnector FB | H29: Disconnector Switch FB | J29: 15 | K29: DO15 | M29: RD:8:O.6 | N29: Dryer Cooling Zone Dust Collector PV02 | O29: =CONCATENATE(K29,E29,N29) -> DO15_Dryer Cooling Zone Dust Collector PV02 | P29: Pulse Valve Coil
A30: 16 | B30: DI16 | D30: RD:4:I.7 | E30: _ | F30: Dryer Cooling Zone Dust Collector Disconnector FB | G30: =CONCATENATE(B30,E30,F30) -> DI16_Dryer Cooling Zone Dust Collector Disconnector FB | H30: Disconnector Switch FB | J30: 16 | K30: DO16 | M30: RD:8:O.7 | N30: Dryer Cooling Zone Dust Collector PV03 | O30: =CONCATENATE(K30,E30,N30) -> DO16_Dryer Cooling Zone Dust Collector PV03 | P30: Pulse Valve Coil
A31: 17 | B31: DI17 | D31: RD:5:I.0 | E31: _ | F31: Dryer Conveyor Motor Disconnector FB | G31: =CONCATENATE(B31,E31,F31) -> DI17_Dryer Conveyor Motor Disconnector FB | H31: Disconnector Switch FB | J31: 17 | K31: DO17 | M31: RD:9:O.0 | N31: Spare DO | O31: =CONCATENATE(K31,E31,N31) -> DO17_Spare DO
A32: 18 | B32: DI18 | D32: RD:5:I.1 | E32: _ | F32: Dryer Outlet Vibratory feeder-1 MPCB Healthy | G32: =CONCATENATE(B32,E32,F32) -> DI18_Dryer Outlet Vibratory feeder-1 MPCB Healthy | H32: MPCB Contact | J32: 18 | K32: DO18 | M32: RD:9:O.1 | N32: Spare DO | O32: =CONCATENATE(K32,E32,N32) -> DO18_Spare DO
A33: 19 | B33: DI19 | D33: RD:5:I.2 | E33: _ | F33: Dryer Outlet Vibratory feeder-2 MPCB Healthy | G33: =CONCATENATE(B33,E33,F33) -> DI19_Dryer Outlet Vibratory feeder-2 MPCB Healthy | H33: MPCB Contact | J33: 19 | K33: DO19 | M33: RD:9:O.2 | N33: Spare DO | O33: =CONCATENATE(K33,E33,N33) -> DO19_Spare DO
A34: 20 | B34: DI20 | D34: RD:5:I.3 | E34: _ | F34: Gas Burner MPCB Healthy | G34: =CONCATENATE(B34,E34,F34) -> DI20_Gas Burner MPCB Healthy | H34: MPCB Contact | J34: 20 | K34: DO20 | M34: RD:9:O.3 | N34: Spare DO | O34: =CONCATENATE(K34,E34,N34) -> DO20_Spare DO
A35: 21 | B35: DI21 | D35: RD:5:I.4 | E35: _ | F35: Dryer Outlet Vibratory feeder-1 Disconnector FB | G35: =CONCATENATE(B35,E35,F35) -> DI21_Dryer Outlet Vibratory feeder-1 Disconnector FB | H35: Disconnector Switch FB | J35: 21 | K35: DO21 | M35: RD:9:O.4 | N35: Gas Burner Enable | O35: =CONCATENATE(K35,E35,N35) -> DO21_Gas Burner Enable | P35: Contact
A36: 22 | B36: DI22 | D36: RD:5:I.5 | E36: _ | F36: Dryer Outlet Vibratory feeder-2 Disconnector FB | G36: =CONCATENATE(B36,E36,F36) -> DI22_Dryer Outlet Vibratory feeder-2 Disconnector FB | H36: Disconnector Switch FB | J36: 22 | K36: DO22 | M36: RD:9:O.5 | N36: Spare DO | O36: =CONCATENATE(K36,E36,N36) -> DO22_Spare DO
A37: 23 | B37: DI23 | D37: RD:5:I.6 | E37: _ | F37: Gas Burner Disconnector FB | G37: =CONCATENATE(B37,E37,F37) -> DI23_Gas Burner Disconnector FB | H37: Disconnector Switch FB | J37: 23 | K37: DO23 | M37: RD:9:O.6 | N37: Spare DO | O37: =CONCATENATE(K37,E37,N37) -> DO23_Spare DO
A38: 24 | B38: DI24 | D38: RD:5:I.7 | E38: _ | F38: Spare DI | G38: =CONCATENATE(B38,E38,F38) -> DI24_Spare DI | J38: 24 | K38: DO24 | M38: RD:9:O.7 | N38: Spare DO | O38: =CONCATENATE(K38,E38,N38) -> DO24_Spare DO
A39: 25 | B39: DI25 | D39: RD:6:I.0 | E39: _ | F39: Gas Burner Healthy FB | G39: =CONCATENATE(B39,E39,F39) -> DI25_Gas Burner Healthy FB | H39: Contact | J39: 25 | K39: DO25 | M39: RD:10:O.0 | N39: Spare DO | O39: =CONCATENATE(K39,E39,N39) -> DO25_Spare DO
A40: 26 | B40: DI26 | D40: RD:6:I.1 | E40: _ | F40: Spare DI | G40: =CONCATENATE(B40,E40,F40) -> DI26_Spare DI | J40: 26 | K40: DO26 | M40: RD:10:O.1 | N40: Spare DO | O40: =CONCATENATE(K40,E40,N40) -> DO26_Spare DO
A41: 27 | B41: DI27 | D41: RD:6:I.2 | E41: _ | F41: Dryer Heating Zone Dust Collector Level High | G41: =CONCATENATE(B41,E41,F41) -> DI27_Dryer Heating Zone Dust Collector Level High | H41: Level Sensor | J41: 27 | K41: DO27 | M41: RD:10:O.2 | N41: Spare DO | O41: =CONCATENATE(K41,E41,N41) -> DO27_Spare DO
A42: 28 | B42: DI28 | D42: RD:6:I.3 | E42: _ | F42: Dryer Cooling Zone Dust Collector Level High | G42: =CONCATENATE(B42,E42,F42) -> DI28_Dryer Cooling Zone Dust Collector Level High | H42: Level Sensor | J42: 28 | K42: DO28 | M42: RD:10:O.3 | N42: Spare DO | O42: =CONCATENATE(K42,E42,N42) -> DO28_Spare DO
A43: 29 | B43: DI29 | D43: RD:6:I.4 | E43: _ | F43: Spare DI | G43: =CONCATENATE(B43,E43,F43) -> DI29_Spare DI | J43: 29 | K43: DO29 | M43: RD:10:O.4 | N43: Spare DO | O43: =CONCATENATE(K43,E43,N43) -> DO29_Spare DO
...

Sheet Packing IO List
A4: DI | J4: DO
A5: Sl No | B5: Input Type | C5: Location | D5: Address | F5: Input Description | G5: Input Tags | H5: Device | I5: TAG | J5: Sl No | K5: Output Type | L5: Location | M5: Address | N5: Output Description | O5: Output Tags | P5: Device | Q5: TAG
F6: DIGITAL INPUT | G6: Input Tags | N6: DIGITAL OUTPUT
A7: 1 | B7: SDI01 | D7: RP:1:I.0 | E7: _ | F7: Bag Filling Area E-Stop 1/1 | G7: =CONCATENATE(B7,E7,F7) -> SDI01_Bag Filling Area E-Stop 1/1 | H7: E-Stop Button | I7: [PLC]RIO01_DI[01] | K7: SDO01 | M7: RP:2:O.0 | N7: Packing Machine Safety Healhy 1/1 | O7: =CONCATENATE(K7,E7,N7) -> SDO01_Packing Machine Safety Healhy 1/1 | P7: Safety Relay (STO)
A8: 2 | B8: SDI02 | D8: RP:1:I.1 | E8: _ | F8: Bag Filling Area E-Stop 1/2 | G8: =CONCATENATE(B8,E8,F8) -> SDI02_Bag Filling Area E-Stop 1/2 | H8: E-Stop Button | I8: [PLC]RIO01_DI[02] | K8: SDO02 | M8: RP:2:O.1 | N8: Packing Machine Safety Healhy 1/2 | O8: =CONCATENATE(K8,E8,N8) -> SDO02_Packing Machine Safety Healhy 1/2 | P8: Safety Relay (STO)
A9: 3 | B9: SDI03 | D9: RP:1:I.2 | E9: _ | F9: Bag Rejection Area E-Stop 1/1 | G9: =CONCATENATE(B9,E9,F9) -> SDI03_Bag Rejection Area E-Stop 1/1 | H9: E-Stop Button | I9: [PLC]RIO01_DI[03] | K9: SDO03 | M9: RP:2:O.2 | N9: Air Service Unit Coil-1 Enable | O9: =CONCATENATE(K9,E9,N9) -> SDO03_Air Service Unit Coil-1 Enable | P9: Air Service Unit Coil
A10: 4 | B10: SDI04 | D10: RP:1:I.3 | E10: _ | F10: Bag Rejection Area E-Stop 1/2 | G10: =CONCATENATE(B10,E10,F10) -> SDI04_Bag Rejection Area E-Stop 1/2 | H10: E-Stop Button | I10: [PLC]RIO01_DI[04] | K10: SDO04 | M10: RP:2:O.3 | N10: Air Service Unit Coil-2 Enable | O10: =CONCATENATE(K10,E10,N10) -> SDO04_Air Service Unit Coil-2 Enable | P10: Air Service Unit Coil
A11: 5 | B11: SDI05 | D11: RP:1:I.4 | E11: _ | F11: Spare DI | G11: =CONCATENATE(B11,E11,F11) -> SDI05_Spare DI | I11: [PLC]RIO01_DI[05] | K11: SDO05 | M11: RP:2:O.4 | O11: =CONCATENATE(K11,E11,N11) -> SDO05_
A12: 6 | B12: SDI06 | D12: RP:1:I.5 | E12: _ | F12: Spare DI | G12: =CONCATENATE(B12,E12,F12) -> SDI06_Spare DI | I12: [PLC]RIO01_DI[06] | K12: SDO06 | M12: RP:2:O.5 | O12: =CONCATENATE(K12,E12,N12) -> SDO06_
A13: 7 | B13: SDI07 | D13: RP:1:I.6 | E13: _ | F13: Spare DI | G13: =CONCATENATE(B13,E13,F13) -> SDI07_Spare DI | I13: [PLC]RIO01_DI[07] | K13: SDO07 | M13: RP:2:O.6 | O13: =CONCATENATE(K13,E13,N13) -> SDO07_
A14: 8 | B14: SDI08 | D14: RP:1:I.7 | E14: _ | F14: Spare DI | G14: =CONCATENATE(B14,E14,F14) -> SDI08_Spare DI | I14: [PLC]RIO01_DI[08] | K14: SDO08 | M14: RP:2:O.7 | O14: =CONCATENATE(K14,E14,N14) -> SDO08_
A15: 1 | B15: DI01 | D15: RP:3:I.0 | E15: _ | F15: Packing Start PB | G15: =CONCATENATE(B15,E15,F15) -> DI01_Packing Start PB | H15: Push Button+Lamp | I15: [PLC]RIO01_DI[09] | K15: DO01 | M15: RP:14:O.0 | N15: Packing Tower Lamp Red | O15: =CONCATENATE(K15,E15,N15) -> DO01_Packing Tower Lamp Red | P15: Tower Lamp
A16: 2 | B16: DI02 | D16: RP:3:I.1 | E16: _ | F16: Packing Stop PB | G16: =CONCATENATE(B16,E16,F16) -> DI02_Packing Stop PB | H16: Push Button | I16: [PLC]RIO01_DI[10] | K16: DO02 | M16: RP:14:O.1 | N16: Packing Tower Lamp Amber | O16: =CONCATENATE(K16,E16,N16) -> DO02_Packing Tower Lamp Amber | P16: Tower Lamp
A17: 3 | B17: DI03 | D17: RP:3:I.2 | E17: _ | F17: Packing System Reset PB | G17: =CONCATENATE(B17,E17,F17) -> DI03_Packing System Reset PB | H17: Push Button+Lamp | I17: [PLC]RIO01_DI[11] | K17: DO03 | M17: RP:14:O.2 | N17: Packing Tower Lamp Green | O17: =CONCATENATE(K17,E17,N17) -> DO03_Packing Tower Lamp Green | P17: Tower Lamp
A18: 4 | B18: DI04 | D18: RP:3:I.3 | E18: _ | F18: Packing System Safety Reset PB | G18: =CONCATENATE(B18,E18,F18) -> DI04_Packing System Safety Reset PB | H18: Push Button+Lamp | I18: [PLC]RIO01_DI[12] | K18: DO04 | M18: RP:14:O.3 | N18: Packing Tower Lamp Buzzer | O18: =CONCATENATE(K18,E18,N18) -> DO04_Packing Tower Lamp Buzzer | P18: Tower Lamp
A19: 5 | B19: DI05 | D19: RP:3:I.4 | E19: _ | F19: Spare DI | G19: =CONCATENATE(B19,E19,F19) -> DI05_Spare DI | I19: [PLC]RIO01_DI[13] | K19: DO05 | M19: RP:14:O.4 | N19: Packing System Start PB Green Lamp | O19: =CONCATENATE(K19,E19,N19) -> DO05_Packing System Start PB Green Lamp | P19: Push Button+Lamp
A20: 6 | B20: DI06 | D20: RP:3:I.5 | E20: _ | F20: 3 Phase Supply Ok | G20: =CONCATENATE(B20,E20,F20) -> DI06_3 Phase Supply Ok | H20: Air Pressure Switch | I20: [PLC]RIO01_DI[14] | K20: DO06 | M20: RP:14:O.5 | N20: Packing System Reset PB Blue Lamp | O20: =CONCATENATE(K20,E20,N20) -> DO06_Packing System Reset PB Blue Lamp | P20: Push Button+Lamp
A21: 7 | B21: DI07 | D21: RP:3:I.6 | E21: _ | F21: Packing Air Pressure Switch | G21: =CONCATENATE(B21,E21,F21) -> DI07_Packing Air Pressure Switch | H21: Phase Failure Relay | I21: [PLC]RIO01_DI[15] | K21: DO07 | M21: RP:14:O.6 | N21: Packing System Safety Reset PB Yellow Lamp | O21: =CONCATENATE(K21,E21,N21) -> DO07_Packing System Safety Reset PB Yellow Lamp | P21: Push Button+Lamp
A22: 8 | B22: DI08 | D22: RP:3:I.7 | E22: _ | F22: Spare DI | G22: =CONCATENATE(B22,E22,F22) -> DI08_Spare DI | I22: [PLC]RIO01_DI[16] | K22: DO08 | M22: RP:14:O.7 | N22: Spare DO | O22: =CONCATENATE(K22,E22,N22) -> DO08_Spare DO
A23: 9 | B23: DI09 | D23: RP:4:I.0 | E23: _ | F23: Incliend Belt conveyor Disconnector FB | G23: =CONCATENATE(B23,E23,F23) -> DI09_Incliend Belt conveyor Disconnector FB | H23: Disconnector Switch FB | I23: [PLC]RIO01_DI[17] | K23: DO09 | M23: RP:15:O.0 | N23: Electro Magnetic Coarse Vibro Enable | O23: =CONCATENATE(K23,E23,N23) -> DO09_Electro Magnetic Coarse Vibro Enable | P23: Contact
A24: 10 | B24: DI10 | D24: RP:4:I.1 | E24: _ | F24: Material Storage Vibro-1 Disconnector FB | G24: =CONCATENATE(B24,E24,F24) -> DI10_Material Storage Vibro-1 Disconnector FB | H24: Disconnector Switch FB | I24: [PLC]RIO01_DI[18] | K24: DO10 | M24: RP:15:O.1 | N24: Electro Magnetic Fine Vibro Enable | O24: =CONCATENATE(K24,E24,N24) -> DO10_Electro Magnetic Fine Vibro Enable | P24: Contact
A25: 11 | B25: DI11 | D25: RP:4:I.2 | E25: _ | F25: Material Storage Vibro-2 Disconnector FB | G25: =CONCATENATE(B25,E25,F25) -> DI11_Material Storage Vibro-2 Disconnector FB | H25: Disconnector Switch FB | I25: [PLC]RIO01_DI[19] | K25: DO11 | M25: RP:15:O.2 | N25: Bag Stitching Motor Enable | O25: =CONCATENATE(K25,E25,N25) -> DO11_Bag Stitching Motor Enable | P25: Contactor
A26: 12 | B26: DI12 | D26: RP:4:I.3 | E26: _ | F26: Bag Filling Conveyor Disconnector FB | G26: =CONCATENATE(B26,E26,F26) -> DI12_Bag Filling Conveyor Disconnector FB | H26: Disconnector Switch FB | I26: [PLC]RIO01_DI[20] | K26: DO12 | M26: RP:15:O.3 | N26: Bagging Zone Dust Collector Enable | O26: =CONCATENATE(K26,E26,N26) -> DO12_Bagging Zone Dust Collector Enable | P26: Contactor
A27: 13 | B27: DI13 | D27: RP:4:I.4 | E27: _ | F27: Bag Sealing & Stiching Conveyor Disconnector FB | G27: =CONCATENATE(B27,E27,F27) -> DI13_Bag Sealing & Stiching Conveyor Disconnector FB | H27: Disconnector Switch FB | I27: [PLC]RIO01_DI[21] | K27: DO13 | M27: RP:15:O.4 | N27: Bag Sealing Machine Enable | O27: =CONCATENATE(K27,E27,N27) -> DO13_Bag Sealing Machine Enable | P27: Contact
A28: 14 | B28: DI14 | D28: RP:4:I.5 | E28: _ | F28: Bag Stitching Motor Trip Healthy | G28: =CONCATENATE(B28,E28,F28) -> DI14_Bag Stitching Motor Trip Healthy | H28: MPCB Contact | I28: [PLC]RIO01_DI[22] | K28: DO14 | M28: RP:15:O.5 | N28: Spare DO | O28: =CONCATENATE(K28,E28,N28) -> DO14_Spare DO
A29: 15 | B29: DI15 | D29: RP:4:I.6 | E29: _ | F29: Bag Tilting Conveyor Disconnector FB | G29: =CONCATENATE(B29,E29,F29) -> DI15_Bag Tilting Conveyor Disconnector FB | H29: Disconnector Switch FB | I29: [PLC]RIO01_DI[23] | K29: DO15 | M29: RP:15:O.6 | N29: Spare DO | O29: =CONCATENATE(K29,E29,N29) -> DO15_Spare DO
A30: 16 | B30: DI16 | D30: RP:4:I.7 | E30: _ | F30: Bag Flattening Bottom Conveyor Disconnector FB | G30: =CONCATENATE(B30,E30,F30) -> DI16_Bag Flattening Bottom Conveyor Disconnector FB | H30: Disconnector Switch FB | I30: [PLC]RIO01_DI[24] | K30: DO16 | M30: RP:15:O.7 | N30: Spare DO | O30: =CONCATENATE(K30,E30,N30) -> DO16_Spare DO
A31: 17 | B31: DI17 | D31: RP:5:I.0 | E31: _ | F31: Bag Flattening Top Conveyor Disconnector FB | G31: =CONCATENATE(B31,E31,F31) -> DI17_Bag Flattening Top Conveyor Disconnector FB | H31: Disconnector Switch FB | I31: [PLC]RIO01_DI[25] | K31: DO17 | M31: RP:16:O.0 | N31: Diverter Flap Cylinder FWD SOV | O31: =CONCATENATE(K31,E31,N31) -> DO17_Diverter Flap Cylinder FWD SOV | P31: SOV Coil
A32: 18 | B32: DI18 | D32: RP:5:I.1 | E32: _ | F32: Metal Detector Conveyor Disconnector FB | G32: =CONCATENATE(B32,E32,F32) -> DI18_Metal Detector Conveyor Disconnector FB | H32: Disconnector Switch FB | I32: [PLC]RIO01_DI[26] | K32: DO18 | M32: RP:16:O.1 | N32: Diverter Flap Cylinder REV SOV | O32: =CONCATENATE(K32,E32,N32) -> DO18_Diverter Flap Cylinder REV SOV | P32: SOV Coil
A33: 19 | B33: DI19 | D33: RP:5:I.2 | E33: _ | F33: Bag Rejection Conveyor Disconnector FB | G33: =CONCATENATE(B33,E33,F33) -> DI19_Bag Rejection Conveyor Disconnector FB | H33: Disconnector Switch FB | I33: [PLC]RIO01_DI[27] | K33: DO19 | M33: RP:16:O.2 | N33: Filling Station Bag Clamp-1/2 Open SOV | O33: =CONCATENATE(K33,E33,N33) -> DO19_Filling Station Bag Clamp-1/2 Open SOV | P33: SOV Coil
A34: 20 | B34: DI20 | D34: RP:5:I.3 | E34: _ | F34: Bagging Zone Dust Collector Trip Healthy | G34: =CONCATENATE(B34,E34,F34) -> DI20_Bagging Zone Dust Collector Trip Healthy | H34: MPCB Contact | I34: [PLC]RIO01_DI[28] | K34: DO20 | M34: RP:16:O.3 | N34: Filling Station Bag Clamp-1/2 Open SOV | O34: =CONCATENATE(K34,E34,N34) -> DO20_Filling Station Bag Clamp-1/2 Open SOV | P34: SOV Coil
A35: 21 | B35: DI21 | D35: RP:5:I.4 | E35: _ | F35: Electro Magnetic Coarse Vibro Trip Healthy | G35: =CONCATENATE(B35,E35,F35) -> DI21_Electro Magnetic Coarse Vibro Trip Healthy | H35: MCB Contact | I35: [PLC]RIO01_DI[29] | K35: DO21 | M35: RP:16:O.4 | N35: Filling Station Bag Side Flap-1/2 Open SOV | O35: =CONCATENATE(K35,E35,N35) -> DO21_Filling Station Bag Side Flap-1/2 Open SOV | P35: SOV Coil
A36: 22 | B36: DI22 | D36: RP:5:I.5 | E36: _ | F36: Electro Magnetic Fine Vibro Trip Healthy | G36: =CONCATENATE(B36,E36,F36) -> DI22_Electro Magnetic Fine Vibro Trip Healthy | H36: MCB Contact | I36: [PLC]RIO01_DI[30] | K36: DO22 | M36: RP:16:O.5 | N36: Filling Station Bag Side Flap-1/2 Close SOV | O36: =CONCATENATE(K36,E36,N36) -> DO22_Filling Station Bag Side Flap-1/2 Close SOV | P36: SOV Coil
A37: 23 | B37: DI23 | D37: RP:5:I.6 | E37: _ | F37: Band Sealer Machine Trip Healthy | G37: =CONCATENATE(B37,E37,F37) -> DI23_Band Sealer Machine Trip Healthy | H37: MCB Contact | I37: [PLC]RIO01_DI[31] | K37: DO23 | M37: RP:16:O.6 | N37: Filling Station Conveyor Up SOV | O37: =CONCATENATE(K37,E37,N37) -> DO23_Filling Station Conveyor Up SOV | P37: SOV Coil
A38: 24 | B38: DI24 | D38: RP:5:I.7 | E38: _ | F38: Spare DI | G38: =CONCATENATE(B38,E38,F38) -> DI24_Spare DI | I38: [PLC]RIO01_DI[32] | K38: DO24 | M38: RP:16:O.7 | N38: Filling Station Conveyor Dn SOV | O38: =CONCATENATE(K38,E38,N38) -> DO24_Filling Station Conveyor Dn SOV | P38: SOV Coil
A39: 25 | B39: DI25 | D39: RP:6:I.0 | E39: _ | F39: Spare DI | G39: =CONCATENATE(B39,E39,F39) -> DI25_Spare DI | I39: [PLC]RIO01_DI[33] | K39: DO25 | M39: RP:17:O.0 | N39: Stitching Station Thread Cutter Cylinder Fwd SOV | O39: =CONCATENATE(K39,E39,N39) -> DO25_Stitching Station Thread Cutter Cylinder Fwd SOV | P39: SOV Coil
A40: 26 | B40: DI26 | D40: RP:6:I.1 | E40: _ | F40: Bag Stitching Motor Disconnector FB | G40: =CONCATENATE(B40,E40,F40) -> DI26_Bag Stitching Motor Disconnector FB | H40: Disconnector Switch FB | I40: [PLC]RIO01_DI[34] | K40: DO26 | M40: RP:17:O.1 | N40: Stitching Station Thread Cutter Cylinder Rev SOV | O40: =CONCATENATE(K40,E40,N40) -> DO26_Stitching Station Thread Cutter Cylinder Rev SOV | P40: SOV Coil
A41: 27 | B41: DI27 | D41: RP:6:I.2 | E41: _ | F41: Bagging Zone Dust Collector Disconnector FB | G41: =CONCATENATE(B41,E41,F41) -> DI27_Bagging Zone Dust Collector Disconnector FB | H41: Disconnector Switch FB | I41: [PLC]RIO01_DI[35] | K41: DO27 | M41: RP:17:O.2 | N41: Rejection Station Pusher Cyl Forward SOV | O41: =CONCATENATE(K41,E41,N41) -> DO27_Rejection Station Pusher Cyl Forward SOV | P41: SOV Coil
A42: 28 | B42: DI28 | D42: RP:6:I.3 | E42: _ | F42: Electro Magnetic Coarse Vibro Disconnector FB | G42: =CONCATENATE(B42,E42,F42) -> DI28_Electro Magnetic Coarse Vibro Disconnector FB | H42: Disconnector Switch FB | I42: [PLC]RIO01_DI[36] | K42: DO28 | M42: RP:17:O.3 | N42: Rejection Station Pusher Cyl Reverse SOV | O42: =CONCATENATE(K42,E42,N42) -> DO28_Rejection Station Pusher Cyl Reverse SOV | P42: SOV Coil
A43: 29 | B43: DI29 | D43: RP:6:I.4 | E43: _ | F43: Electro Magnetic Fine Vibro Disconnector FB | G43: =CONCATENATE(B43,E43,F43) -> DI29_Electro Magnetic Fine Vibro Disconnector FB | H43: Disconnector Switch FB | I43: [PLC]RIO01_DI[37] | K43: DO29 | M43: RP:17:O.4 | N43: Spare DO | O43: =CONCATENATE(K43,E43,N43) -> DO29_Spare DO
...

Sheet Network
B2: Project Network

Sheet Drive
K1: 13 | L1: 5 | M1: 2 | N1: 1 | O1: 1 | P1: 2
C2: Chopper Motor-1 | D2: CM001 | E2: VFD | F2: 3.7 | H2: 3.7 | K2: 0.75 | L2: 1.5 | M2: 3.7 | N2: 5.5 | O2: 7.5 | P2: 22.5
C3: Chopper Motor-2 | D3: CM002 | E3: VFD | F3: 3.7 | H3: 3.7
C4: Anti-Static Coating Roller | D4: ASCR001 | E4: VFD | F4: 0.75 | H4: 0.5
C5: Spreader Motor-2 | D5: SM001 | E5: VFD | F5: 0.75 | H5: 0.5
C6: Feeders-1 (In Future Scope) | D6: - | E6: VFD | F6: 0.75 | H6: 0.18
C7: Feeders-2 (In Future Scope) | D7: - | E7: VFD | F7: 0.75 | H7: 0.18
C8: Feeders-3 (In Future Scope) | D8: - | E8: VFD | F8: 0.75 | H8: 0.37
C9: Dryer Heating Zone Inlet Blower | D9: DHIB01 | E9: VFD | F9: 22.5 | H9: 22.5
C10: Dryer Heating Zone Dust Collector | D10: DHDC01 | E10: VFD | F10: 22.5 | H10: 22.5
C11: Dryer Cooling Zone Inlet Blower | D11: DCIB01 | E11: VFD | F11: 5.5 | H11: 5.5
C12: Dryer Cooling Zone Dust Collector | D12: DCDC01 | E12: VFD | F12: 7.5 | H12: 7.5
C13: Dryer Conveyor Motor | D13: DCM | E13: VFD | F13: 1.5 | H13: 1.1
C14: Incliend Belt conveyor | D14: IBC001 | E14: VFD | F14: 1.5 | H14: 1.1
... C25: Bagging Zone Dust Collector | D25: BDCB01 | E25: DOL | F25: 1.5 | H25: 1.1
