Workbook

Sheet Electrical Load_Frame-1
D1: Efficiency | E1: 0.8 | G1: CYBERNETIK
D2: Power Factor | E2: 0.5 | G2: Total KW | H2: =SUM(H25,H32) -> 19.52
D3: Line to Line Voltage | E3: 480 | G3: Total HP | H3: =(H2/$E$5) -> 26.16622
D4: Single Phase voltage | E4: 120 | G4: Total Amp | H4: =(H2*1000)/(1.73*$E$3*$E$2) -> 47.013487
D5: KW to HP Conversion | E5: 0.746 | G5: Design Total KW | H5: =H2*$E$6 -> 24.4
D6: Design Factor | E6: 1.25 | G6: Design Total HP | H6: =H3*$E$6 -> 32.707775
D7: KVA to KW Conversion | E7: 0.8 | G7: Design Total Amp | H7: =H4*$E$6 -> 58.766859
D8: Robot Supply Transformer | E8: 230
B10: CYBERNETIK MACHINE
B11: Zone | C11: Sr. No | D11: Device | E11: Name | F11: DOL/VFD | G11: KW | H11: Total (KW) | I11: HP | J11: Amp
B12: Frame-1 | C12: 1 | D12: Tray Pusher Servo 01 | E12: TPS01 | F12: C3-SERVO | G12: 1.5 | H12: =G12 -> 1.5 | I12: =H12/$E$5 -> 2.0107239 | J12: 3
C13: 2 | D13: Plate Pusher Servo 01 | E13: PPS01 | F13: C3-SERVO | G13: 1.5 | H13: =G13 -> 1.5 | I13: =H13/$E$5 -> 2.0107239 | J13: 3
C14: 3 | D14: Plate Guide Servo 01 | E14: PGS01 | F14: C3-SERVO | G14: 1.5 | H14: =G14 -> 1.5 | I14: =H14/$E$5 -> 2.0107239 | J14: 3
C15: 4 | D15: Tray Pusher Servo 02 | E15: TPS02 | F15: C3-SERVO | G15: 1.5 | H15: =G15 -> 1.5 | I15: =H15/$E$5 -> 2.0107239 | J15: 3
C16: 5 | D16: Plate Pusher Servo 02 | E16: PPS02 | F16: C3-SERVO | G16: 1.5 | H16: =G16 -> 1.5 | I16: =H16/$E$5 -> 2.0107239 | J16: 3
C17: 6 | D17: Plate Guide Servo 02 | E17: PGS02 | F17: C3-SERVO | G17: 1.5 | H17: =G17 -> 1.5 | I17: =H17/$E$5 -> 2.0107239 | J17: 3
C18: 7 | D18: Plate Feeding Conveyor | E18: PFC01 | F18: PF525 | G18: 0.75 | H18: =G18 -> 0.75 | I18: =H18/$E$5 -> 1.0053619 | J18: =(H18*1000)/(1.732*$E$1*$E$2*$E$3) -> 2.2553406
C19: 8 | D19: Tray Feeding Conveyor | E19: TFC01 | F19: PF525 | G19: 0.75 | H19: =G19 -> 0.75 | I19: =H19/$E$5 -> 1.0053619 | J19: =(H19*1000)/(1.732*$E$1*$E$2*$E$3) -> 2.2553406
C20: 9 | D20: Printer Assembly Servo Slide | E20: PASS01 | F20: C5-SERVO | G20: 2.2 | H20: =G20 -> 2.2 | I20: =H20/$E$5 -> 2.9490617 | J20: =(H20*1000)/(1.732*$E$1*$E$2*$E$3) -> 6.6156659
B21: Frame-2 | C21: 10 | D21: Tray Insertion Servo Slide | E21: TIS01 | F21: C3-SERVO | G21: 1.5 | H21: =G21 -> 1.5 | I21: =H21/$E$5 -> 2.0107239 | J21: =(H21*1000)/(1.732*$E$1*$E$2*$E$3) -> 4.5106813
C22: 11 | D22: Sealing Conveyor | E22: SLC01 | F22: PF525 | G22: 0.75 | H22: =G22 -> 0.75 | I22: =H22/$E$5 -> 1.0053619 | J22: =(H22*1000)/(1.732*$E$1*$E$2*$E$3) -> 2.2553406
C23: 12 | D23: Vacuum Pump | E23: VPM01 | F23: DOL | G23: 0.37 | H23: =G23 -> 0.37 | I23: =H23/$E$5 -> 0.49597855 | J23: =(H23*1000)/(1.732*$E$1*$E$2*$E$3) -> 1.1126347
C24: 13 | D24: Bag Heat Sealer (Vacuum Pump + Sealer) | E24: BHS01 | F24: Supply | G24: 2.2 | H24: =G24 -> 2.2 | I24: =H24/$E$5 -> 2.9490617 | J24: =(H24*1000)/(1.732*$E$1*$E$2*$E$3) -> 6.6156659
C25: Total | G25: =SUM(G12:G24) -> 17.52 | H25: =SUM(H12:H24) -> 17.52 | I25: =SUM(I12:I24) -> 23.485255 | J25: =SUM(J12:J24) -> 43.62067
B26: Resistive Load
B27: Zone | C27: Sr. No | D27: Device | E27: Name | F27: KVA | G27: KW | H27: Total (KW) | I27: HP | J27: Amp
B28: Frame-1 Single Phase | C28: 1 | D28: Tray Transfer ROBOT | E28: TTR01 | G28: 0.5 | H28: =G28 -> 0.5 | I28: =H28/$E$5 -> 0.67024129 | J28: =(H28*1000/E8)/E1 -> 2.7173913
C29: 2 | D29: Plate Handling ROBOT-1 | E29: PHR01 | G29: 0.5 | H29: =G29 -> 0.5 | I29: =H29/$E$5 -> 0.67024129 | J29: =(H29*1000/E8)/E1 -> 2.7173913
C30: 3 | D30: Plate Handling ROBOT-2 | E30: PHR02 | G30: 0.5 | H30: =G30 -> 0.5 | I30: =H30/$E$5 -> 0.67024129 | J30: =(H30*1000/E8)/E1 -> 2.7173913
B31: Frame-2 Single Phase | C31: 4 | D31: Bag Transfer Robot | E31: BTR01 | G31: 0.5 | H31: =G31 -> 0.5 | I31: =H31/$E$5 -> 0.67024129 | J31: =(H31*1000/E8)/E1 -> 2.7173913
C32: Total | G32: =SUM(G28:G31) -> 2 | H32: =SUM(H28:H31) -> 2 | I32: =SUM(I28:I31) -> 2.6809651 | J32: =SUM(J28:J31) -> 10.869565
B33: Total Designed(1.25) | G33: =H5 -> 24.4 | H33: =H5 -> 24.4 | I33: =H6 -> 32.707775 | J33: =H7 -> 58.766859
B34: UPS Load
B35: Zone | C35: Sr. No | D35: Device | E35: Name | F35: KVA | G35: KW | H35: Total (KW) | I35: HP | J35: Amp | K35: S Amp
B36: Control & Utility | C36: 1 | D36: Control and Utility UPS | E36: UPS | F36: 3 | G36: 3 | H36: 3 | I36: =H36/$E$5 -> 4.0214477 | J36: =(H36*1000/E4)/E1 -> 31.25 | K36: =J36 -> 31.25
D37: (PLC, SCADA PC, I/O)
D38: Printer 01 Supply (100 Watt)
D39: Printer 02 Supply (100 Watt)
B40: Frame-1 Single Phase | D40: Bowl Feeder-1 Bowl Motor | E40: Transformer | G40: 1 | H40: =G40 -> 1 | I40: =H40/$E$5 -> 1.3404826 | J40: =(H40*1000/$E$8)/$E$5 -> 5.8281851 | K40: =J40 -> 5.8281851
D41: Bowl Feeder-1 Linear Motor | G41: 0.5 | H41: =G41 -> 0.5 | I41: =H41/$E$5 -> 0.67024129 | J41: =(H41*1000/$E$8)/$E$5 -> 2.9140926 | K41: =J41 -> 2.9140926
...

Sheet Electrical Load_Frame-2
D1: Efficiency | E1: 0.8 | G1: CYBERNETIK
D2: Power Factor | E2: 0.5 | G2: Total KW | H2: =SUM(H16,H20) -> 5.32
D3: Line to Line Voltage | E3: 480 | G3: Total HP | H3: =(H2/$E$5) -> 7.1313673
D4: Single Phase voltage | E4: 120 | G4: Total Amp | H4: =(H2*1000)/(1.73*$E$3*$E$2) -> 12.813102
D5: KW to HP Conversion | E5: 0.746 | G5: Design Total KW | H5: =H2*$E$6 -> 6.65
D6: Design Factor | E6: 1.25 | G6: Design Total HP | H6: =H3*$E$6 -> 8.9142091
D7: KVA to KW Conversion | E7: 0.8 | G7: Design Total Amp | H7: =H4*$E$6 -> 16.016378
D8: Robot Supply Transformer | E8: 230
B10: CYBERNETIK MACHINE
B11: Zone | C11: Sr. No | D11: Device | E11: Name | F11: DOL/VFD | G11: KW | H11: Total (KW) | I11: HP | J11: Amp
B12: Frame-2 | C12: 1 | D12: Tray Insertion Servo Slide | E12: TIS01 | F12: C3-SERVO | G12: 1.5 | H12: =G12 -> 1.5 | I12: =H12/$E$5 -> 2.0107239 | J12: 3
C13: 2 | D13: Sealing Conveyor | E13: SLC01 | F13: PF525 | G13: 0.75 | H13: =G13 -> 0.75 | I13: =H13/$E$5 -> 1.0053619 | J13: =(H13*1000)/(1.732*$E$1*$E$2*$E$3) -> 2.2553406
C14: 3 | D14: Vacuum Pump | E14: VPM01 | F14: DOL | G14: 0.37 | H14: =G14 -> 0.37 | I14: =H14/$E$5 -> 0.49597855 | J14: =(H14*1000)/(1.732*$E$1*$E$2*$E$3) -> 1.1126347
C15: 4 | D15: Bag Heat Sealer (Vacuum Pump + Sealer) | E15: BHS01 | F15: Supply | G15: 2.2 | H15: =G15 -> 2.2 | I15: =H15/$E$5 -> 2.9490617 | J15: =(H15*1000)/(1.732*$E$1*$E$2*$E$3) -> 6.6156659
C16: Total | G16: =SUM(G12:G15) -> 4.82 | H16: =SUM(H12:H15) -> 4.82 | I16: =SUM(I12:I15) -> 6.461126 | J16: =SUM(J12:J15) -> 12.983641
B17: Resistive Load
B18: Zone | C18: Sr. No | D18: Device | E18: Name | F18: KVA | G18: KW | H18: Total (KW) | I18: HP | J18: Amp
B19: ROBOT | C19: 1 | D19: Bag Transfer Robot | E19: BTR01 | G19: 0.5 | H19: =G19 -> 0.5 | I19: =H19/$E$5 -> 0.67024129 | J19: =(H19*1000/E8)/E1 -> 2.7173913
C20: Total | G20: =SUM(G19) -> 0.5 | H20: =SUM(H19) -> 0.5 | I20: =SUM(I19) -> 0.67024129 | J20: =SUM(J19) -> 2.7173913
B21: Total Designed(1.25) | G21: =H5 -> 6.65 | H21: =H5 -> 6.65 | I21: =H6 -> 8.9142091 | J21: =H7 -> 16.016378
K47: 2 Nodes

Sheet Network

Sheet Frame-1 IO
B3: DI | K3: DO
B4: Sl No | D4: Address | E4: Space | F4: Input Description | H4: Device | I4: Area | J4: Tag | K4: Sl No | M4: Address | N4: Output Description | P4: Device | Q4: Area | R4: Tag
F5: New | N5: New
F6: DIGITAL INPUT | G6: Input Tags | N6: DIGITAL OUTPUT | O6: Output Tags
B7: 1 | C7: SDI01 | D7: R1:I:1.0 | E7: _ | F7: Emergency Stop @ HMI Panel 1/1 | G7: =CONCATENATE(C7,E7,F7) -> SDI01_Emergency Stop @ HMI Panel 1/1 | H7: E-Stop button | J7: F01-ESS1/1 | K7: 1 | L7: SDO01 | M7: R1:O:3.0 | N7: Frame-1 STO Safety Relay On_1/1 | O7: =CONCATENATE(L7,E7,N7) -> SDO01_Frame-1 STO Safety Relay On_1/1 | P7: Safety Relay | R7: F01-STO1/1
B8: 2 | C8: SDI02 | D8: R1:I:1.1 | E8: _ | F8: Emergency Stop @ HMI Panel 1/2 | G8: =CONCATENATE(C8,E8,F8) -> SDI02_Emergency Stop @ HMI Panel 1/2 | H8: E-Stop button | J8: F01-ESS1/2 | K8: 2 | L8: SDO02 | M8: R1:O:3.1 | N8: Frame-1 STO Safety Relay On_1/2 | O8: =CONCATENATE(L8,E8,N8) -> SDO02_Frame-1 STO Safety Relay On_1/2 | P8: Safety Relay | R8: F01-STO1/2
B9: 3 | C9: SDI03 | D9: R1:I:1.2 | E9: _ | F9: Frame-1 Door Switch-1/1 | G9: =CONCATENATE(C9,E9,F9) -> SDI03_Frame-1 Door Switch-1/1 | H9: Door Switch | J9: F01-DSW1/1 | K9: 3 | L9: SDO03 | M9: R1:O:3.2 | N9: Safety Relay and Air Shutoff Valve Healthy 1/1 | O9: =CONCATENATE(L9,E9,N9) -> SDO03_Safety Relay and Air Shutoff Valve Healthy 1/1 | P9: Safety Relay | R9: F01-STOA/1
B10: 4 | C10: SDI04 | D10: R1:I:1.3 | E10: _ | F10: Frame-1 Door Switch-1/2 | G10: =CONCATENATE(C10,E10,F10) -> SDI04_Frame-1 Door Switch-1/2 | H10: Door Switch | J10: F01-DSW1/2 | K10: 4 | L10: SDO04 | M10: R1:O:3.3 | N10: Safety Relay and Air Shutoff Valve Healthy 1/2 | O10: =CONCATENATE(L10,E10,N10) -> SDO04_Safety Relay and Air Shutoff Valve Healthy 1/2 | P10: Safety Relay | R10: F01-STOA/2
B11: 5 | C11: SDI05 | D11: R1:I:1.4 | E11: _ | F11: Frame-1 Door Switch-2/1 | G11: =CONCATENATE(C11,E11,F11) -> SDI05_Frame-1 Door Switch-2/1 | H11: Door Switch | J11: F01-DSW2/1 | K11: 5 | L11: SDO05 | M11: R1:O:3.4 | N11: Frame-1 Robot Auto Stop Relay Healthy 1/1 | O11: =CONCATENATE(L11,E11,N11) -> SDO05_Frame-1 Robot Auto Stop Relay Healthy 1/1 | P11: Safety Relay | R11: F01-RAS1/1
B12: 6 | C12: SDI06 | D12: R1:I:1.5 | E12: _ | F12: Frame-1 Door Switch-2/2 | G12: =CONCATENATE(C12,E12,F12) -> SDI06_Frame-1 Door Switch-2/2 | H12: Door Switch | J12: F01-DSW2/2 | K12: 6 | L12: SDO06 | M12: R1:O:3.5 | N12: Frame-1 Robot Auto Stop Relay Healthy 1/2 | O12: =CONCATENATE(L12,E12,N12) -> SDO06_Frame-1 Robot Auto Stop Relay Healthy 1/2 | P12: Safety Relay | R12: F01-RAS1/2
B13: 7 | C13: SDI07 | D13: R1:I:1.6 | E13: _ | F13: Frame-1 Door Switch-3/1 | G13: =CONCATENATE(C13,E13,F13) -> SDI07_Frame-1 Door Switch-3/1 | H13: Door Switch | J13: F01-DSW3/1 | K13: 7 | L13: SDO07 | M13: R1:O:3.6 | N13: Frame-1 Robot E-Stop Relay Healthy 1/1 | O13: =CONCATENATE(L13,E13,N13) -> SDO07_Frame-1 Robot E-Stop Relay Healthy 1/1 | P13: Safety Relay | R13: F01-RES1/1
B14: 8 | C14: SDI08 | D14: R1:I:1.7 | E14: _ | F14: Frame-1 Door Switch-3/2 | G14: =CONCATENATE(C14,E14,F14) -> SDI08_Frame-1 Door Switch-3/2 | H14: Door Switch | J14: F01-DSW3/2 | K14: 8 | L14: SDO08 | M14: R1:O:3.7 | N14: Frame-1 Robot E-Stop Relay Healthy 1/2 | O14: =CONCATENATE(L14,E14,N14) -> SDO08_Frame-1 Robot E-Stop Relay Healthy 1/2 | P14: Safety Relay | R14: F01-RES1/2
B15: 9 | C15: SDI09 | D15: R1:I:2.0 | E15: _ | F15: Frame-1 Tray Door Switch-4/1 | G15: =CONCATENATE(C15,E15,F15) -> SDI09_Frame-1 Tray Door Switch-4/1 | H15: Door Switch | J15: F01-DSW4/1 | K15: 9 | L15: SDO09 | M15: R1:O:4.0 | N15: Frame-1 Door Switch Coil-1,2,3/1 | O15: =CONCATENATE(L15,E15,N15) -> SDO09_Frame-1 Door Switch Coil-1,2,3/1 | P15: Safety Relay +Door Coil | R15: F01-DSW1,2,3/1
B16: 10 | C16: SDI10 | D16: R1:I:2.1 | E16: _ | F16: Frame-1 Tray Door Switch-4/2 | G16: =CONCATENATE(C16,E16,F16) -> SDI10_Frame-1 Tray Door Switch-4/2 | H16: Door Switch | J16: F01-DSW4/2 | K16: 10 | L16: SDO10 | M16: R1:O:4.1 | N16: Frame-1 Door Switch Coil-1,2,3/2 | O16: =CONCATENATE(L16,E16,N16) -> SDO10_Frame-1 Door Switch Coil-1,2,3/2 | P16: Safety Relay +Door Coil | R16: F01-DSW1,2,3/2
B17: 11 | C17: SDI11 | D17: R1:I:2.2 | E17: _ | F17: Frame-1 Tray Door Switch-5/1 | G17: =CONCATENATE(C17,E17,F17) -> SDI11_Frame-1 Tray Door Switch-5/1 | H17: Door Switch | J17: F01-DSW5/1 | K17: 11 | L17: SDO11 | M17: R1:O:4.2 | N17: Frame-1 Tray Door Switch Coil-4/1 | O17: =CONCATENATE(L17,E17,N17) -> SDO11_Frame-1 Tray Door Switch Coil-4/1 | P17: Safety Relay +Door Coil | R17: F01-DSW4/1
B18: 12 | C18: SDI12 | D18: R1:I:2.3 | E18: _ | F18: Frame-1 Tray Door Switch-5/2 | G18: =CONCATENATE(C18,E18,F18) -> SDI12_Frame-1 Tray Door Switch-5/2 | H18: Door Switch | J18: F01-DSW5/2 | K18: 12 | L18: SDO12 | M18: R1:O:4.3 | N18: Frame-1 Tray Door Switch Coil-4/2 | O18: =CONCATENATE(L18,E18,N18) -> SDO12_Frame-1 Tray Door Switch Coil-4/2 | P18: Safety Relay +Door Coil | R18: F01-DSW4/2
B19: 13 | C19: SDI13 | D19: R1:I:2.4 | E19: _ | F19: Tray Stacker Safety Cover Slide Position 01 FB | G19: =CONCATENATE(C19,E19,F19) -> SDI13_Tray Stacker Safety Cover Slide Position 01 FB | H19: Magnetic Door Switch | K19: 13 | L19: SDO13 | M19: R1:O:4.4 | N19: Frame-1 Tray Door Switch Coil-5/1 | O19: =CONCATENATE(L19,E19,N19) -> SDO13_Frame-1 Tray Door Switch Coil-5/1 | P19: Safety Relay +Door Coil | R19: F01-DSW5/1
B20: 14 | C20: SDI14 | D20: R1:I:2.5 | E20: _ | F20: Tray Stacker Safety Cover Slide Position 02 FB | G20: =CONCATENATE(C20,E20,F20) -> SDI14_Tray Stacker Safety Cover Slide Position 02 FB | H20: Magnetic Door Switch | K20: 14 | L20: SDO14 | M20: R1:O:4.5 | N20: Frame-1 Tray Door Switch Coil-5/2 | O20: =CONCATENATE(L20,E20,N20) -> SDO14_Frame-1 Tray Door Switch Coil-5/2 | P20: Safety Relay +Door Coil | R20: F01-DSW5/2
B21: 15 | C21: SDI15 | D21: R1:I:2.6 | E21: _ | F21: Spare DI | G21: =CONCATENATE(C21,E21,F21) -> SDI15_Spare DI | K21: 15 | L21: SDO15 | M21: R1:O:4.6 | N21: Spare DO | O21: =CONCATENATE(L21,E21,N21) -> SDO15_Spare DO
B22: 16 | C22: SDI16 | D22: R1:I:2.7 | E22: _ | F22: Spare DI | G22: =CONCATENATE(C22,E22,F22) -> SDI16_Spare DI | K22: 16 | L22: SDO16 | M22: R1:O:4.7 | N22: Spare DO | O22: =CONCATENATE(L22,E22,N22) -> SDO16_Spare DO
B23: 1 | C23: DI01 | D23: R1:5:I.0 | E23: _ | F23: System Start PB @ HMI Panel | G23: =CONCATENATE(C23,E23,F23) -> DI01_System Start PB @ HMI Panel | H23: Push Button + Lamp | I23: Safe | J23: PBL01 | K23: 1 | L23: DO01 | M23: R:11:O.0 | N23: Tower Lamp Red @ HMI Panel | O23: =CONCATENATE(L23,E23,N23) -> DO01_Tower Lamp Red @ HMI Panel | P23: Tower lamp | Q23: Safe | R23: TL-101/1
B24: 2 | C24: DI02 | D24: R1:5:I.1 | E24: _ | F24: System Stop PB @ HMI Panel | G24: =CONCATENATE(C24,E24,F24) -> DI02_System Stop PB @ HMI Panel | H24: Push Button + Lamp | I24: Safe | J24: PBL02 | K24: 2 | L24: DO02 | M24: R:11:O.1 | N24: Tower Lamp Amber@ HMI Panel | O24: =CONCATENATE(L24,E24,N24) -> DO02_Tower Lamp Amber@ HMI Panel | P24: Tower lamp | Q24: Safe | R24: TL-101/2
B25: 3 | C25: DI03 | D25: R1:5:I.2 | E25: _ | F25: System Reset PB @ HMI Panel | G25: =CONCATENATE(C25,E25,F25) -> DI03_System Reset PB @ HMI Panel | H25: Push Button + Lamp | I25: Safe | J25: PBL03 | K25: 3 | L25: DO03 | M25: R:11:O.2 | N25: Tower Lamp Green@ HMI Panel | O25: =CONCATENATE(L25,E25,N25) -> DO03_Tower Lamp Green@ HMI Panel | P25: Tower lamp | Q25: Safe | R25: TL-101/3
B26: 4 | C26: DI04 | D26: R1:5:I.3 | E26: _ | F26: Safety Reset PB @ HMI Panel | G26: =CONCATENATE(C26,E26,F26) -> DI04_Safety Reset PB @ HMI Panel | H26: Push Button + Lamp | I26: Safe | J26: PBL04 | K26: 4 | L26: DO04 | M26: R:11:O.3 | N26: Tower Lamp Buzzer@ HMI Panel | O26: =CONCATENATE(L26,E26,N26) -> DO04_Tower Lamp Buzzer@ HMI Panel | P26: Tower lamp | Q26: Safe | R26: TL-101/4
B27: 5 | C27: DI05 | D27: R1:5:I.4 | E27: _ | F27: Line Monitor Relay Healthy | G27: =CONCATENATE(C27,E27,F27) -> DI05_Line Monitor Relay Healthy | I27: Safe | K27: 5 | L27: DO05 | M27: R:11:O.4 | N27: System Start Lamp | O27: =CONCATENATE(L27,E27,N27) -> DO05_System Start Lamp | P27: Push + Lamp | Q27: Safe | R27: PBL01
B28: 6 | C28: DI06 | D28: R1:5:I.5 | E28: _ | F28: Spare DI | G28: =CONCATENATE(C28,E28,F28) -> DI06_Spare DI | I28: Safe | K28: 6 | L28: DO06 | M28: R:11:O.5 | N28: System Reset Lamp | O28: =CONCATENATE(L28,E28,N28) -> DO06_System Reset Lamp | P28: Push + Lamp | Q28: Safe | R28: PBL03
B29: 7 | C29: DI07 | D29: R1:5:I.6 | E29: _ | F29: Spare DI | G29: =CONCATENATE(C29,E29,F29) -> DI07_Spare DI | I29: Safe | K29: 7 | L29: DO07 | M29: R:11:O.6 | N29: Safety Reset Lamp | O29: =CONCATENATE(L29,E29,N29) -> DO07_Safety Reset Lamp | P29: Push + Lamp | Q29: Safe | R29: PBL04
B30: 8 | C30: DI08 | D30: R1:5:I.7 | E30: _ | F30: Air Pressure Switch | G30: =CONCATENATE(C30,E30,F30) -> DI08_Air Pressure Switch | H30: Pressure Switch | I30: Safe | J30: PSW01 | K30: 8 | L30: DO08 | M30: R:11:O.7 | N30: Spare DO | O30: =CONCATENATE(L30,E30,N30) -> DO08_Spare DO | Q30: Safe
B31: 9 | C31: DI09 | D31: R1:6:I.0 | E31: _ | F31: Tray Pusher Servo 01 Trip Healthy | G31: =CONCATENATE(C31,E31,F31) -> DI09_Tray Pusher Servo 01 Trip Healthy | H31: MPCB Contact | I31: Safe | K31: 9 | L31: DO09 | M31: R:12:O.0 | N31: Vacuum Pump Enable | O31: =CONCATENATE(L31,E31,N31) -> DO09_Vacuum Pump Enable | P31: Contactor | Q31: Safe | R31: VPM01
B32: 10 | C32: DI10 | D32: R1:6:I.1 | E32: _ | F32: Plate Pusher Servo 01 Trip Healthy | G32: =CONCATENATE(C32,E32,F32) -> DI10_Plate Pusher Servo 01 Trip Healthy | H32: MPCB Contact | I32: Safe | K32: 10 | L32: DO10 | M32: R:12:O.1 | N32: Spare DO | O32: =CONCATENATE(L32,E32,N32) -> DO10_Spare DO | Q32: Safe
B33: 11 | C33: DI11 | D33: R1:6:I.2 | E33: _ | F33: Plate Guide Servo 01 Trip Healthy | G33: =CONCATENATE(C33,E33,F33) -> DI11_Plate Guide Servo 01 Trip Healthy | H33: MPCB Contact | I33: Safe | K33: 11 | L33: DO11 | M33: R:12:O.2 | N33: Plate Feeding Machine Start Signal | O33: =CONCATENATE(L33,E33,N33) -> DO11_Plate Feeding Machine Start Signal | P33: Contact | Q33: Safe
B34: 12 | C34: DI12 | D34: R1:6:I.3 | E34: _ | F34: Tray Pusher Servo 02 Trip Healthy | G34: =CONCATENATE(C34,E34,F34) -> DI12_Tray Pusher Servo 02 Trip Healthy | H34: MPCB Contact | I34: Safe | K34: 12 | L34: DO12 | M34: R:12:O.3 | N34: Bowl Feeder 01 Enable Signal | O34: =CONCATENATE(L34,E34,N34) -> DO12_Bowl Feeder 01 Enable Signal | P34: Contact | Q34: Safe
B35: 13 | C35: DI13 | D35: R1:6:I.4 | E35: _ | F35: Plate Pusher Servo 02 Trip Healthy | G35: =CONCATENATE(C35,E35,F35) -> DI13_Plate Pusher Servo 02 Trip Healthy | H35: MPCB Contact | I35: Safe | K35: 13 | L35: DO13 | M35: R:12:O.4 | N35: Linear Feeder 01 Enable Signal | O35: =CONCATENATE(L35,E35,N35) -> DO13_Linear Feeder 01 Enable Signal | P35: Contact | Q35: Safe
B36: 14 | C36: DI14 | D36: R1:6:I.5 | E36: _ | F36: Plate Guide Servo 02 Trip Healthy | G36: =CONCATENATE(C36,E36,F36) -> DI14_Plate Guide Servo 02 Trip Healthy | H36: MPCB Contact | I36: Safe | K36: 14 | L36: DO14 | M36: R:12:O.5 | N36: Linear Feeder 01 High Speed Signal | O36: =CONCATENATE(L36,E36,N36) -> DO14_Linear Feeder 01 High Speed Signal | P36: Contact | Q36: Safe
B37: 15 | C37: DI15 | D37: R1:6:I.6 | E37: _ | F37: Plate Feeding Conveyor Trip Healthy | G37: =CONCATENATE(C37,E37,F37) -> DI15_Plate Feeding Conveyor Trip Healthy | H37: MPCB Contact | I37: Safe | K37: 15 | L37: DO15 | M37: R:12:O.6 | N37: Linear Feeder 01 Slow Speed Signal | O37: =CONCATENATE(L37,E37,N37) -> DO15_Linear Feeder 01 Slow Speed Signal | P37: Contact | Q37: Safe
B38: 16 | C38: DI16 | D38: R1:6:I.7 | E38: _ | F38: Tray Feeding Conveyor Trip Healthy | G38: =CONCATENATE(C38,E38,F38) -> DI16_Tray Feeding Conveyor Trip Healthy | H38: MPCB Contact | I38: Safe | K38: 16 | L38: DO16 | M38: R:12:O.7 | N38: Bowl Feeder 02 Enable Signal | O38: =CONCATENATE(L38,E38,N38) -> DO16_Bowl Feeder 02 Enable Signal | P38: Contact | Q38: Safe
B39: 17 | C39: DI17 | D39: R1:7:I.0 | E39: _ | F39: Printer Assembly Servo Slide Trip Healthy | G39: =CONCATENATE(C39,E39,F39) -> DI17_Printer Assembly Servo Slide Trip Healthy | H39: MPCB Contact | I39: Safe | K39: 17 | L39: DO17 | M39: R:13:O.0 | N39: Linear Feeder 02 Enable Signal | O39: =CONCATENATE(L39,E39,N39) -> DO17_Linear Feeder 02 Enable Signal | P39: Contact | Q39: Safe
B40: 18 | C40: DI18 | D40: R1:7:I.1 | E40: _ | F40: Spare DI | G40: =CONCATENATE(C40,E40,F40) -> DI18_Spare DI | I40: Safe | K40: 18 | L40: DO18 | M40: R:13:O.1 | N40: Linear Feeder 02 High Speed Signal | O40: =CONCATENATE(L40,E40,N40) -> DO18_Linear Feeder 02 High Speed Signal | P40: Contact | Q40: Safe
B41: 19 | C41: DI19 | D41: R1:7:I.2 | E41: _ | F41: Power Panel Frame 02 Trip Healthy | G41: =CONCATENATE(C41,E41,F41) -> DI19_Power Panel Frame 02 Trip Healthy | H41: MPCB Contact | I41: Safe | K41: 19 | L41: DO19 | M41: R:13:O.2 | N41: Linear Feeder 02 Slow Speed Signal | O41: =CONCATENATE(L41,E41,N41) -> DO19_Linear Feeder 02 Slow Speed Signal | P41: Contact | Q41: Safe
B42: 20 | C42: DI20 | D42: R1:7:I.3 | E42: _ | F42: Bowl Feeder Bowl Motor 01 Trip Healthy | G42: =CONCATENATE(C42,E42,F42) -> DI20_Bowl Feeder Bowl Motor 01 Trip Healthy | H42: MCB Healthy | I42: Safe | K42: 20 | L42: DO20 | M42: R:13:O.3 | N42: Printer 01 Head 01 Print Signal | O42: =CONCATENATE(L42,E42,N42) -> DO20_Printer 01 Head 01 Print Signal | P42: Contact | Q42: Safe
...

Sheet Frame-2 IO
B3: DI | K3: DO
B4: Sl No | D4: Address | E4: Space | F4: Input Description | H4: Device | I4: Area | J4: Tag | K4: Sl No | M4: Address | N4: Output Description | P4: Device | Q4: Area | R4: Tag
F5: New | N5: New
F6: DIGITAL INPUT | G6: Input Tags | N6: DIGITAL OUTPUT | O6: Output Tags
B7: 1 | C7: SDI01 | D7: R2:I:1.0 | E7: _ | F7: Emergency Stop @ Frame-2 1/1 | G7: =CONCATENATE(C7,E7,F7) -> SDI01_Emergency Stop @ Frame-2 1/1 | H7: E-Stop button | J7: F02-ESS1/1 | K7: 1 | L7: SDO01 | M7: R2:O:4.0 | N7: Frame-2 STO Safety Relay On_1/1 | O7: =CONCATENATE(L7,E7,N7) -> SDO01_Frame-2 STO Safety Relay On_1/1 | P7: Safety Relay | R7: F02-STO1/1
B8: 2 | C8: SDI02 | D8: R2:I:1.1 | E8: _ | F8: Emergency Stop @ Frame-2 1/2 | G8: =CONCATENATE(C8,E8,F8) -> SDI02_Emergency Stop @ Frame-2 1/2 | H8: E-Stop button | J8: F02-ESS1/2 | K8: 2 | L8: SDO02 | M8: R2:O:4.1 | N8: Frame-2 STO Safety Relay On_1/2 | O8: =CONCATENATE(L8,E8,N8) -> SDO02_Frame-2 STO Safety Relay On_1/2 | P8: Safety Relay | R8: F02-STO1/2
B9: 3 | C9: SDI03 | D9: R2:I:1.2 | E9: _ | F9: Frame-2 Door Switch-1/1 | G9: =CONCATENATE(C9,E9,F9) -> SDI03_Frame-2 Door Switch-1/1 | H9: Door Switch | J9: F02-DSW1/1 | K9: 3 | L9: SDO03 | M9: R2:O:4.2 | N9: Frame-2 Robot Auto Stop Relay Healthy 1/1 | O9: =CONCATENATE(L7,E7,N9) -> SDO01_Frame-2 Robot Auto Stop Relay Healthy 1/1 | P9: Safety Relay | R9: F02-RAS1/1
B10: 4 | C10: SDI04 | D10: R2:I:1.3 | E10: _ | F10: Frame-2 Door Switch-1/2 | G10: =CONCATENATE(C10,E10,F10) -> SDI04_Frame-2 Door Switch-1/2 | H10: Door Switch | J10: F02-DSW1/2 | K10: 4 | L10: SDO04 | M10: R2:O:4.3 | N10: Frame-2 Robot Auto Stop Relay Healthy 1/2 | O10: =CONCATENATE(L8,E8,N10) -> SDO02_Frame-2 Robot Auto Stop Relay Healthy 1/2 | P10: Safety Relay | R10: F02-RAS1/2
B11: 5 | C11: SDI05 | D11: R2:I:1.4 | E11: _ | F11: Frame-2 Door Switch-2/1 | G11: =CONCATENATE(C11,E11,F11) -> SDI05_Frame-2 Door Switch-2/1 | H11: Door Switch | J11: F02-DSW2/1 | K11: 5 | L11: SDO05 | M11: R2:O:4.4 | N11: Frame-2 Robot E-Stop Relay Healthy 1/1 | O11: =CONCATENATE(L9,E9,N11) -> SDO03_Frame-2 Robot E-Stop Relay Healthy 1/1 | P11: Safety Relay | R11: F02-RES1/1
B12: 6 | C12: SDI06 | D12: R2:I:1.5 | E12: _ | F12: Frame-2 Door Switch-2/2 | G12: =CONCATENATE(C12,E12,F12) -> SDI06_Frame-2 Door Switch-2/2 | H12: Door Switch | J12: F02-DSW2/2 | K12: 6 | L12: SDO06 | M12: R2:O:4.5 | N12: Frame-2 Robot E-Stop Relay Healthy 1/2 | O12: =CONCATENATE(L10,E10,N12) -> SDO04_Frame-2 Robot E-Stop Relay Healthy 1/2 | P12: Safety Relay | R12: F02-RES1/2
B13: 7 | C13: SDI07 | D13: R2:I:1.6 | E13: _ | F13: Frame-2 Door Switch-3/1 | G13: =CONCATENATE(C13,E13,F13) -> SDI07_Frame-2 Door Switch-3/1 | H13: Door Switch | J13: F02-DSW3/1 | K13: 7 | L13: SDO07 | M13: R2:O:4.6 | N13: Frame-2 Door Switch Coil-1,2,3,4,5,6/1 | O13: =CONCATENATE(L11,E11,N13) -> SDO05_Frame-2 Door Switch Coil-1,2,3,4,5,6/1 | P13: Safety Relay +Door Coil | R13: F02-DSW1,2,3,4,5,6/1
B14: 8 | C14: SDI08 | D14: R2:I:1.7 | E14: _ | F14: Frame-2 Door Switch-3/2 | G14: =CONCATENATE(C14,E14,F14) -> SDI08_Frame-2 Door Switch-3/2 | H14: Door Switch | J14: F02-DSW3/2 | K14: 8 | L14: SDO08 | M14: R2:O:4.7 | N14: Frame-2 Door Switch Coil-1,2,3,4,5,6/2 | O14: =CONCATENATE(L12,E12,N14) -> SDO06_Frame-2 Door Switch Coil-1,2,3,4,5,6/2 | P14: Safety Relay +Door Coil | R14: F02-DSW1,2,3,4,5,6/2
B15: 9 | C15: SDI09 | D15: R2:I:2.0 | E15: _ | F15: Frame-2 Door Switch-4/1 | G15: =CONCATENATE(C15,E15,F15) -> SDI09_Frame-2 Door Switch-4/1 | H15: Door Switch | J15: F02-DSW4/1 | K15: 9 | L15: SDO09 | M15: R2:O:5.0 | N15: Frame-2 Bag Bin-1 Door Switch Coil-7/1 | O15: =CONCATENATE(L13,E13,N15) -> SDO07_Frame-2 Bag Bin-1 Door Switch Coil-7/1 | P15: Safety Relay +Door Coil | R15: F02-DSW7/1
B16: 10 | C16: SDI10 | D16: R2:I:2.1 | E16: _ | F16: Frame-2 Door Switch-4/2 | G16: =CONCATENATE(C16,E16,F16) -> SDI10_Frame-2 Door Switch-4/2 | H16: Door Switch | J16: F02-DSW4/2 | K16: 10 | L16: SDO10 | M16: R2:O:5.1 | N16: Frame-2 Bag Bin-1 Door Switch Coil-7/2 | O16: =CONCATENATE(L14,E14,N16) -> SDO08_Frame-2 Bag Bin-1 Door Switch Coil-7/2 | P16: Safety Relay +Door Coil | R16: F02-DSW7/2
B17: 11 | C17: SDI11 | D17: R2:I:2.2 | E17: _ | F17: Frame-2 Door Switch-5/1 | G17: =CONCATENATE(C17,E17,F17) -> SDI11_Frame-2 Door Switch-5/1 | H17: Door Switch | J17: F02-DSW5/1 | K17: 11 | L17: SDO11 | M17: R2:O:5.2 | N17: Frame-2 Bag Bin-2 Door Switch Coil-8/1 | O17: =CONCATENATE(L15,E15,N17) -> SDO09_Frame-2 Bag Bin-2 Door Switch Coil-8/1 | P17: Safety Relay +Door Coil | R17: F02-DSW8/1
B18: 12 | C18: SDI12 | D18: R2:I:2.3 | E18: _ | F18: Frame-2 Door Switch-5/2 | G18: =CONCATENATE(C18,E18,F18) -> SDI12_Frame-2 Door Switch-5/2 | H18: Door Switch | J18: F02-DSW5/2 | K18: 12 | L18: SDO12 | M18: R2:O:5.3 | N18: Frame-2 Bag Bin-2 Door Switch Coil-8/2 | O18: =CONCATENATE(L16,E16,N18) -> SDO10_Frame-2 Bag Bin-2 Door Switch Coil-8/2 | P18: Safety Relay +Door Coil | R18: F02-DSW8/2
B19: 13 | C19: SDI13 | D19: R2:I:2.4 | E19: _ | F19: Frame-2 Door Switch-6/1 | G19: =CONCATENATE(C19,E19,F19) -> SDI13_Frame-2 Door Switch-6/1 | H19: Door Switch | J19: F02-DSW6/1 | K19: 13 | L19: SDO13 | M19: R2:O:5.4 | N19: Spare DO | O19: =CONCATENATE(L19,E19,N19) -> SDO13_Spare DO
B20: 14 | C20: SDI14 | D20: R2:I:2.5 | E20: _ | F20: Frame-2 Door Switch-6/2 | G20: =CONCATENATE(C20,E20,F20) -> SDI14_Frame-2 Door Switch-6/2 | H20: Door Switch | J20: F02-DSW6/2 | K20: 14 | L20: SDO14 | M20: R2:O:5.5 | N20: Spare DO | O20: =CONCATENATE(L20,E20,N20) -> SDO14_Spare DO
B21: 15 | C21: SDI15 | D21: R2:I:2.6 | E21: _ | F21: Frame-2 Bag Bin-1 Door Switch-7/1 | G21: =CONCATENATE(C21,E21,F21) -> SDI15_Frame-2 Bag Bin-1 Door Switch-7/1 | H21: Door Switch | J21: F02-DSW7/1 | K21: 15 | L21: SDO15 | M21: R2:O:5.6 | N21: Spare DO | O21: =CONCATENATE(L21,E21,N21) -> SDO15_Spare DO
B22: 16 | C22: SDI16 | D22: R2:I:2.7 | E22: _ | F22: Frame-2 Bag Bin-1 Door Switch-7/2 | G22: =CONCATENATE(C22,E22,F22) -> SDI16_Frame-2 Bag Bin-1 Door Switch-7/2 | H22: Door Switch | J22: F02-DSW7/2 | K22: 16 | L22: SDO16 | M22: R2:O:5.7 | N22: Spare DO | O22: =CONCATENATE(L22,E22,N22) -> SDO16_Spare DO
B23: 17 | C23: SDI17 | D23: R2:I:3.0 | E23: _ | F23: Frame-2 Bag Bin-2 Door Switch-8/1 | G23: =CONCATENATE(C23,E23,F23) -> SDI17_Frame-2 Bag Bin-2 Door Switch-8/1 | H23: Door Switch | J23: F02-DSW8/1
B24: 18 | C24: SDI18 | D24: R2:I:3.1 | E24: _ | F24: Frame-2 Bag Bin-2 Door Switch-8/2 | G24: =CONCATENATE(C24,E24,F24) -> SDI18_Frame-2 Bag Bin-2 Door Switch-8/2 | H24: Door Switch | J24: F02-DSW8/2
B25: 19 | C25: SDI19 | D25: R2:I:3.2 | E25: _ | F25: Bag Bin Safety Cover Slide Position 01 FB | G25: =CONCATENATE(C25,E25,F25) -> SDI19_Bag Bin Safety Cover Slide Position 01 FB
B26: 20 | C26: SDI20 | D26: R2:I:3.3 | E26: _ | F26: Bag Bin Safety Cover Slide Position 02 FB | G26: =CONCATENATE(C26,E26,F26) -> SDI20_Bag Bin Safety Cover Slide Position 02 FB
B27: 21 | C27: SDI21 | D27: R2:I:3.4 | E27: _ | F27: Spare DI | G27: =CONCATENATE(C27,E27,F27) -> SDI21_Spare DI
B28: 22 | C28: SDI22 | D28: R2:I:3.5 | E28: _ | F28: Spare DI | G28: =CONCATENATE(C28,E28,F28) -> SDI22_Spare DI
B29: 23 | C29: SDI23 | D29: R2:I:3.6 | E29: _ | F29: Spare DI | G29: =CONCATENATE(C29,E29,F29) -> SDI23_Spare DI
B30: 24 | C30: SDI24 | D30: R2:I:3.7 | E30: _ | F30: Spare DI | G30: =CONCATENATE(C30,E30,F30) -> SDI24_Spare DI
B31: 1 | C31: DI01 | D31: R21:6:I.0 | E31: _ | F31: Tray Insertion Servo Slide Trip Healthy | G31: =CONCATENATE(C31,E31,F31) -> DI01_Tray Insertion Servo Slide Trip Healthy | H31: MPCB Contact | I31: Safe | K31: 1 | L31: DO01 | M31: R2:8:O.0 | N31: Vacuum Pump Enable | O31: =CONCATENATE(L31,E31,N31) -> DO01_Vacuum Pump Enable | P31: Contactor | Q31: Safe
B32: 2 | C32: DI02 | D32: R21:6:I.1 | E32: _ | F32: Sealing Conveyor Trip Healthy | G32: =CONCATENATE(C32,E32,F32) -> DI02_Sealing Conveyor Trip Healthy | H32: MPCB Contact | I32: Safe | K32: 2 | L32: DO02 | M32: R2:8:O.1 | N32: Bag Sealer Vacuum Pump Enable | O32: =CONCATENATE(L32,E32,N32) -> DO02_Bag Sealer Vacuum Pump Enable | P32: Contactor | Q32: Safe
B33: 3 | C33: DI03 | D33: R21:6:I.2 | E33: _ | F33: Vacuum Pump Trip Healthy | G33: =CONCATENATE(C33,E33,F33) -> DI03_Vacuum Pump Trip Healthy | H33: MPCB Contact | I33: Safe | K33: 3 | L33: DO03 | M33: R2:8:O.2 | N33: Bag Heat Sealer Enable | O33: =CONCATENATE(L33,E33,N33) -> DO03_Bag Heat Sealer Enable | P33: SSR | Q33: Safe
B34: 4 | C34: DI04 | D34: R21:6:I.3 | E34: _ | F34: Bag Sealer Vacuum Pump Trip Healthy | G34: =CONCATENATE(C34,E34,F34) -> DI04_Bag Sealer Vacuum Pump Trip Healthy | H34: MPCB Contact | I34: Safe | K34: 4 | L34: DO04 | M34: R2:8:O.3 | N34: Spare DO | O34: =CONCATENATE(L34,E34,N34) -> DO04_Spare DO | Q34: Safe
B35: 5 | C35: DI05 | D35: R21:6:I.4 | E35: _ | F35: Bag Heat Sealer Trip Healthy | G35: =CONCATENATE(C35,E35,F35) -> DI05_Bag Heat Sealer Trip Healthy | H35: RCCB Contact | I35: Safe | K35: 5 | L35: DO05 | M35: R2:8:O.4 | N35: Spare DO | O35: =CONCATENATE(L35,E35,N35) -> DO05_Spare DO | Q35: Safe
B36: 6 | C36: DI06 | D36: R21:6:I.5 | E36: _ | F36: Spare DI | G36: =CONCATENATE(C36,E36,F36) -> DI06_Spare DI | I36: Safe | K36: 6 | L36: DO06 | M36: R2:8:O.5 | N36: Spare DO | O36: =CONCATENATE(L36,E36,N36) -> DO06_Spare DO | Q36: Safe
B37: 7 | C37: DI07 | D37: R21:6:I.6 | E37: _ | F37: Spare DI | G37: =CONCATENATE(C37,E37,F37) -> DI07_Spare DI | I37: Safe | K37: 7 | L37: DO07 | M37: R2:8:O.6 | N37: Spare DO | O37: =CONCATENATE(L37,E37,N37) -> DO07_Spare DO | Q37: Safe
B38: 8 | C38: DI08 | D38: R21:6:I.7 | E38: _ | F38: Spare DI | G38: =CONCATENATE(C38,E38,F38) -> DI08_Spare DI | I38: Safe | K38: 8 | L38: DO08 | M38: R2:8:O.7 | N38: Spare DO | O38: =CONCATENATE(L38,E38,N38) -> DO08_Spare DO | Q38: Safe
B39: 9 | C39: DI09 | D39: R21:7:I.0 | E39: _ | F39: Spare DI | G39: =CONCATENATE(C39,E39,F39) -> DI09_Spare DI | I39: Safe
B40: 10 | C40: DI10 | D40: R21:7:I.1 | E40: _ | F40: Spare DI | G40: =CONCATENATE(C40,E40,F40) -> DI10_Spare DI | I40: Safe
B41: 11 | C41: DI11 | D41: R21:7:I.2 | E41: _ | F41: Spare DI | G41: =CONCATENATE(C41,E41,F41) -> DI11_Spare DI | I41: Safe
B42: 12 | C42: DI12 | D42: R21:7:I.3 | E42: _ | F42: Spare DI | G42: =CONCATENATE(C42,E42,F42) -> DI12_Spare DI | I42: Safe
...

Sheet Device
D1: Device | G1: PLC Tag | J1: IP Adress
C2: 1 | D2: PLC | E2: PLC01 | J2: 192.052.020.031
C3: 2 | D3: AENTR IO 01 | E3: RIO01 | J3: 192.052.020.033
C4: 3 | D4: AENTR IO 02 | E4: RIO02 | J4: 192.052.020.034
C5: 4 | D5: Remote Module 01 | E5: RM01 | J5: 192.052.020.035
C6: 5 | D6: Remote Module 02 | E6: RM02 | J6: 192.052.020.036
C7: 6 | D7: Scada | E7: SCADA01 | J7: 192.052.020.038
C8: 7 | D8: Tray Pusher Servo 01 | E8: TPS01 | F8: C3-SERVO | G8: FB_Servo01 | H8: _ | I8: FB_Servo01_TPS01 | J8: 192.052.020.048
C9: 8 | D9: Plate Pusher Servo 01 | E9: PPS01 | F9: C3-SERVO | G9: FB_Servo02 | H9: _ | I9: FB_Servo02_PPS01 | J9: 192.052.020.049
C10: 9 | D10: Plate Guide Servo 01 | E10: PGS01 | F10: C3-SERVO | G10: FB_Servo03 | H10: _ | I10: FB_Servo03_PGS01 | J10: 192.052.020.050
C11: 10 | D11: Tray Pusher Servo 02 | E11: TPS02 | F11: C3-SERVO | G11: FB_Servo04 | H11: _ | I11: FB_Servo04_TPS02 | J11: 192.052.020.051
C12: 11 | D12: Plate Pusher Servo 02 | E12: PPS02 | F12: C3-SERVO | G12: FB_Servo05 | H12: _ | I12: FB_Servo05_PPS02 | J12: 192.052.020.052
C13: 12 | D13: Plate Guide Servo 02 | E13: PGS02 | F13: C3-SERVO | G13: FB_Servo06 | H13: _ | I13: FB_Servo06_PGS02 | J13: 192.052.020.053
C14: 13 | D14: Printer Assembly Servo Slide | E14: PASS01 | F14: C5-SERVO | G14: FB_Servo07 | H14: _ | I14: FB_Servo07_PASS01 | J14: 192.052.020.047
C15: 14 | D15: Tray Insertion Servo Slide | E15: TIS01 | F15: C3-SERVO | G15: FB_Servo08 | H15: _ | I15: FB_Servo08_TIS01 | J15: 192.052.020.055
C16: 15 | D16: Tray Stacker Servo 01 | E16: TST01 | F16: CMMT-ST | G16: FB_Servo09 | H16: _ | I16: FB_Servo09_TST01 | J16: 192.052.020.044
C17: 16 | D17: Tray Stacker Servo 02 | E17: TST02 | F17: CMMT-ST | G17: FB_Servo10 | H17: _ | I17: FB_Servo10_TST02 | J17: 192.052.020.045
C18: 17 | D18: Plate Feeding Conveyor | E18: PFC01 | F18: PF525 | G18: FB_Drive01 | H18: _ | I18: FB_Drive01_PFC01 | J18: 192.052.020.046
C19: 18 | D19: Tray Feeding Conveyor | E19: TFC01 | F19: PF525 | G19: FB_Drive02 | H19: _ | I19: FB_Drive02_TFC01 | J19: 192.052.020.054
... C23: 22 | D23: Vacuum Pump | E23: VPM01 | F23: DOL | G23: FB_DOL03 | H23: _ | I23: FB_DOL03_VPM01 | J23: NA
B24: New Added | C24: 23 | D24: Bag Sealer Vacuum Pump | E24: BSVPM01 | F24: DOL | G24: FB_DOL04 | H24: _ | I24: FB_DOL04_BSVP01 | J24: 192.052.020.040
C25: 24 | D25: Plate Handling ROBOT-1 | E25: Robot 01 | F25: ABB | G25: FB_ROB01 | H25: _ | I25: FB_ROB01_Robot 01 | J25: 192.052.020.041
C26: 25 | D26: Plate Handling ROBOT-2 | E26: Robot 02 | F26: ABB | G26: FB_ROB02 | H26: _ | I26: FB_ROB02_Robot 02 | J26: 192.052.020.039
C27: 26 | D27: Tray Transfer ROBOT | E27: Robot 03 | F27: ABB | G27: FB_ROB03 | H27: _ | I27: FB_ROB03_Robot 03 | J27: 192.052.020.057
C28: 27 | D28: Bag Transfer Robot | E28: Robot 04 | F28: ABB | G28: FB_ROB04 | H28: _ | I28: FB_ROB04_Robot 04
C29: 28 | H29: _ | I29: =CONCATENATE(G29,H29,E29) -> _
C30: 29 | H30: _ | I30: =CONCATENATE(G30,H30,E30) -> _
D33: Description | E33: Cyl Qty | G33: PLC Tag /FB No | I33: FB Description | J33: Pos01 | K33: Pos02 | L33: IP01 | M33: IP02 | N33: OP01 | O33: OP02
C34: 1 | D34: Plate Infeed Conveyor Diverter | E34: 1 | G34: FB_PV01 | H34: _ | I34: =CONCATENATE(G34,H34,D34) -> FB_PV01_Plate Infeed Conveyor Diverter | J34: Pos01 | K34: Pos02
B35: Plate Handling ROBOT 01 Gripper | C35: 2 | D35: Linear Feeder 01 Exit Stopper | E35: 1 | G35: FB_PV02 | H35: _ | I35: =CONCATENATE(G35,H35,D35) -> FB_PV02_Linear Feeder 01 Exit Stopper | J35: Open | K35: Close
B36: Plate Handling ROBOT 01 Swing | C36: 3 | D36: Linear Feeder 02 Exit Stopper | E36: 1 | G36: FB_PV03 | H36: _ | I36: =CONCATENATE(G36,H36,D36) -> FB_PV03_Linear Feeder 02 Exit Stopper | J36: Open | K36: Close
B37: Tray 01 Side Guide | C37: 4 | D37: Plate Handling ROBOT 01 Gripper | E37: 1 | G37: FB_PV04 | H37: _ | I37: =CONCATENATE(G37,H37,D37) -> FB_PV04_Plate Handling ROBOT 01 Gripper | J37: Fwd | K37: Rev
B38: Tray 01 Front Guide | C38: 5 | D38: Tray 01 Side Guide | E38: 1 | G38: FB_PV05 | H38: _ | I38: =CONCATENATE(G38,H38,D38) -> FB_PV05_Tray 01 Side Guide | J38: Fwd | K38: Rev
B39: Tray 01 Stopper 01/02 | C39: 6 | D39: Tray 01 Front Guide | E39: 1 | G39: FB_PV06 | H39: _ | I39: =CONCATENATE(G39,H39,D39) -> FB_PV06_Tray 01 Front Guide | J39: Up | K39: Down
B40: Tray 01 Pusher UP FB | C40: 7 | D40: Tray 01 Stopper 01/02 | E40: 2 | G40: FB_PV07 | H40: _ | I40: =CONCATENATE(G40,H40,D40) -> FB_PV07_Tray 01 Stopper 01/02 | J40: Up | K40: Down
B41: Plate Handling ROBOT 02 Gripper | C41: 8 | D41: Tray 01 Pusher UP FB | E41: 1 | G41: FB_PV08 | H41: _ | I41: =CONCATENATE(G41,H41,D41) -> FB_PV08_Tray 01 Pusher UP FB | J41: Open | K41: Close
B42: Plate Handling ROBOT 02 Swing | C42: 9 | D42: Plate Handling ROBOT 02 Gripper | E42: 1 | G42: FB_PV09 | H42: _ | I42: =CONCATENATE(G42,H42,D42) -> FB_PV09_Plate Handling ROBOT 02 Gripper | J42: Open | K42: Close
C43: 10 | D43: Tray 02 Side Guide | E43: 1 | G43: FB_PV10 | H43: _ | I43: =CONCATENATE(G43,H43,D43) -> FB_PV10_Tray 02 Side Guide | J43: Fwd | K43: Rev
C44: 11 | D44: Tray 02 Front Guide | E44: 1 | G44: FB_PV11 | H44: _ | I44: =CONCATENATE(G44,H44,D44) -> FB_PV11_Tray 02 Front Guide | J44: Fwd | K44: Rev
C45: 12 | D45: Tray 02 Stopper 01/02 | E45: 2 | G45: FB_PV12 | H45: _ | I45: =CONCATENATE(G45,H45,D45) -> FB_PV12_Tray 02 Stopper 01/02 | J45: Up | K45: Down
...

Sheet Alarms
B1: Alarm
B2: Communication_Alarm
B3: SR.No | C3: ErrorCode_ | F3: Device | G3: Alarm Description | H3: Alarm_Message
B4: 1 | C4: E001 | F4: AENTR IO 01 | G4: Communication Faulted | H4: =CONCATENATE(C4,D4,E4,F4,D4,G4) -> E001 AENTR IO 01 Communication Faulted
B5: 2 | C5: E002 | F5: AENTR IO 02 | G5: Communication Faulted | H5: =CONCATENATE(C5,D5,E5,F5,D5,G5) -> E002 AENTR IO 02 Communication Faulted
B6: 3 | C6: E003 | F6: Remote IO 01 | G6: Communication Faulted | H6: =CONCATENATE(C6,D6,E6,F6,D6,G6) -> E003 Remote IO 01 Communication Faulted
B7: 4 | C7: E004 | F7: Remote IO 02 | G7: Communication Faulted | H7: =CONCATENATE(C7,D7,E7,F7,D7,G7) -> E004 Remote IO 02 Communication Faulted
B8: 5 | C8: E005 | F8: Tray Pusher Servo 01 | G8: Drive Communication Faulted | H8: =CONCATENATE(C8,D8,E8,F8,D8,G8) -> E005 Tray Pusher Servo 01 Drive Communication Faulted
B9: 6 | C9: E006 | F9: Plate Pusher Servo 01 | G9: Drive Communication Faulted | H9: =CONCATENATE(C9,D9,E9,F9,D9,G9) -> E006 Plate Pusher Servo 01 Drive Communication Faulted
B10: 7 | C10: E007 | F10: Plate Guide Servo 01 | G10: Drive Communication Faulted | H10: =CONCATENATE(C10,D10,E10,F10,D10,G10) -> E007 Plate Guide Servo 01 Drive Communication Faulted
B11: 8 | C11: E008 | F11: Tray Pusher Servo 02 | G11: Drive Communication Faulted | H11: =CONCATENATE(C11,D11,E11,F11,D11,G11) -> E008 Tray Pusher Servo 02 Drive Communication Faulted
B12: 9 | C12: E009 | F12: Plate Pusher Servo 02 | G12: Drive Communication Faulted | H12: =CONCATENATE(C12,D12,E12,F12,D12,G12) -> E009 Plate Pusher Servo 02 Drive Communication Faulted
B13: 10 | C13: E010 | F13: Plate Guide Servo 02 | G13: Drive Communication Faulted | H13: =CONCATENATE(C13,D13,E13,F13,D13,G13) -> E010 Plate Guide Servo 02 Drive Communication Faulted
B14: 11 | C14: E011 | F14: Printer Assembly Servo Slide | G14: Drive Communication Faulted | H14: =CONCATENATE(C14,D14,E14,F14,D14,G14) -> E011 Printer Assembly Servo Slide Drive Communication Faulted
B15: 12 | C15: E012 | F15: Tray Insertion Servo Slide | G15: Drive Communication Faulted | H15: =CONCATENATE(C15,D15,E15,F15,D15,G15) -> E012 Tray Insertion Servo Slide Drive Communication Faulted
... B25: 22 | C25: E022 | F25: Valve Bank | G25: Communication Faulted | H25: =CONCATENATE(C25,D25,E25,F25,D25,G25) -> E022 Valve Bank Communication Faulted
B26: 23 | C26: E023 | F26: Spare | H26: =CONCATENATE(C26,D26,E26,F26,D26,G26) -> E023 Spare
B27: 24 | C27: E024 | F27: Spare | H27: =CONCATENATE(C27,D27,E27,F27,D27,G27) -> E024 Spare
B28: 25 | C28: E025 | H28: =CONCATENATE(C28,D28,E28,F28,D28,G28) -> E025
B29: 26 | C29: E026 | H29: =CONCATENATE(C29,D29,E29,F29,D29,G29) -> E026
B30: 27 | C30: E027 | H30: =CONCATENATE(C30,D30,E30,F30,D30,G30) -> E027
B31: 28 | C31: E028 | H31: =CONCATENATE(C31,D31,E31,F31,D31,G31) -> E028
B32: 29 | C32: E029 | H32: =CONCATENATE(C32,D32,E32,F32,D32,G32) -> E029
B33: 30 | C33: E030 | H33: =CONCATENATE(C33,D33,E33,F33,D33,G33) -> E030
B34: 31 | C34: E031 | H34: =CONCATENATE(C34,D34,E34,F34,D34,G34) -> E031
B35: 32 | C35: E032 | H35: =CONCATENATE(C35,D35,E35,F35,D35,G35) -> E032
B36: 33 | C36: E101 | F36: Air Pressure | G36: Low | H36: =CONCATENATE(C36,D36,E36,F36,D36,G36) -> E101 Air Pressure Low
B37: 34 | C37: E102 | F37: E-Stop At HMI | G37: Pressed | H37: =CONCATENATE(C37,D37,E37,F37,D37,G37) -> E102 E-Stop At HMI Pressed
B38: 35 | C38: E103 | F38: E-Stop At Fame 02 | G38: Pressed | H38: =CONCATENATE(C38,D38,E38,F38,D38,G38) -> E103 E-Stop At Fame 02 Pressed
B39: 36 | C39: E104 | F39: Frame 01 Door 01 | G39: Open | H39: =CONCATENATE(C39,D39,E39,F39,D39,G39) -> E104 Frame 01 Door 01 Open
B40: 37 | C40: E105 | F40: Frame 01 Door 02 | G40: Open | H40: =CONCATENATE(C40,D40,E40,F40,D40,G40) -> E105 Frame 01 Door 02 Open
B41: 38 | C41: E106 | F41: Frame 01 Door 03 | G41: Open | H41: =CONCATENATE(C41,D41,E41,F41,D41,G41) -> E106 Frame 01 Door 03 Open
B42: 39 | C42: E107 | F42: Frame 01 Tray 01 Door 04 | G42: Open | H42: =CONCATENATE(C42,D42,E42,F42,D42,G42) -> E107 Frame 01 Tray 01 Door 04 Open
B43: 40 | C43: E108 | F43: Frame 01 Tray 02 Door 05 | G43: Open | H43: =CONCATENATE(C43,D43,E43,F43,D43,G43) -> E108 Frame 01 Tray 02 Door 05 Open
B44: 41 | C44: E109 | F44: Frame 02 Door 01 | G44: Open | H44: =CONCATENATE(C44,D44,E44,F44,D44,G44) -> E109 Frame 02 Door 01 Open
B45: 42 | C45: E110 | F45: Frame 02 Door 02 | G45: Open | H45: =CONCATENATE(C45,D45,E45,F45,D45,G45) -> E110 Frame 02 Door 02 Open
B46: 43 | C46: E111 | F46: Frame 02 Door 03 | G46: Open | H46: =CONCATENATE(C46,D46,E46,F46,D46,G46) -> E111 Frame 02 Door 03 Open
B47: 44 | C47: E112 | F47: Frame 02 Door 04 | G47: Open | H47: =CONCATENATE(C47,D47,E47,F47,D47,G47) -> E112 Frame 02 Door 04 Open
... B51: 48 | C51: E116 | F51: Frame 02 Bag Bin 02 Door 08 | G51: Open | H51: =CONCATENATE(C51,D51,E51,F51,D51,G51) -> E116 Frame 02 Bag Bin 02 Door 08 Open
B52: 49 | C52: E117 | F52: Tray Stacker Safety Cover | H52: =CONCATENATE(C52,D52,E52,F52,D52,G52) -> E117 Tray Stacker Safety Cover
...

Sheet Sheet3
J12: DI01
J13: DI02
J14: DI03
J15: DI04
J16: DI05
J17: DI06
J18: DI07
J19: DI08
J20: DI09
J21: DI10
J22: DI11
J23: DI12
